Workbook

Sheet 사용법
A1: 창업진흥원 근무평정 점수 보정 실무 계산서
A2: 개정안 [별표 9] 「평가자별 평가점수의 보정 방법」을 엑셀 수식으로 구현한 파일
A4: 고지 — 이 파일의 모든 인명·점수는 산식 검증을 위한 모의 예시 데이터이며, 창업진흥원의 실제 근무평정 결과가 아니다.
A5: 이 파일은 조합이 2026년 2분기 노사협의회에 제출하는 개정안 [별표 9]의 구현이다. 정본은 docs/amendments.md 이며, 이 파일과 정본이 어긋나면 정본이 우선한다.
A7: 이 파일을 만든 이유
A8: 1. 검산 가능성의 증명 — 조합은 「검산할 수 없는 산식은 규정에 담을 수 없다」를 원칙으로 세웠고, 그 이유로 혼합효과 모형·Bradley-Terry·경험베이즈 등 고급 기법을 전부 폐기했다. 이 파일은 개정안 산식이 엑셀 수식 몇 줄로 구현된다는 물증이다. 모든 셀은 값이 아니라 수식이다 — 셀을 클릭해 확인하라.
A9: 2. MIS 개선 요청 명세 — 내부경영정보시스템 근무평정 모듈에 이 계산을 넣도록 요청할 때의 기능 명세서가 된다(⑦ 시트).
A11: 셀 색 구분
A12: 입력 셀 — 실무자가 채운다 | B12: 원점수 · 제7호 조정량 · 조정 사유 · 다면평가 점수 · 유효 응답 수 · 공통평가 점수 · 부서장 여부 · 배점 스위치
A13: 자동 계산 셀 — 손대지 않는다 | B13: 인원 n · 순위 r · s(n) · z · 보정점수 · 조정 후 점수 · 종합점수 · 등급 · 평정점 · 모든 검증 판정
A14: 고지 · 경고 | B14: 동점 입력 경고, 모의 데이터 고지 등 반드시 읽어야 하는 문구
A15: PASS / FAIL | B15: ⑤ 검증 시트의 판정. 녹색이 PASS, 적색이 FAIL이다. FAIL이 하나라도 있으면 입력을 다시 확인하라.
A17: 작업 순서
A18: 순서 | B18: 시트 | C18: 무엇을 하는가
A19: 1 | B19: ② 평가군 계산 | C19: 평가자명 · 평가군 구분(1차/2차) · 직급 · 피평가자 · 원점수를 입력한다. 평가군은 「동일 평가자 · 동일 평가구분 · 동일 직급군」이다([별표 9] 제1호). 평가군마다 행을 붙여서 쓴다.
A20: 2 | B20: ② 동점 확인 | C20: 4행의 「동점 입력 건수」가 0건인지 확인한다. 동점이 있으면 순위가 중복되어 산식이 깨진다. 개정 2가 동점을 금지하므로 정상 운용에서는 발생하지 않지만 입력 오류를 여기서 잡는다.
A21: 3 | B21: ② 제5호 확인 | C21: 인원 n이 6명 미만인 평가군은 「제5호 미실시」로 자동 표시되고, 2차 평가자의 보정점수가 자동으로 기준점수가 된다. 2차도 6명 미만이면 80점이 들어간다.
A22: 4 | B22: ② 제7호 조정 | C22: 1차 평가자가 조정란(±5점)에 입력한다. ⑤ 검증 시트에서 평가군별 합계가 0.00인지 확인한다. 조정한 피평가자는 사유란을 반드시 채운다. 2차 평가자는 조정하지 아니한다.
A23: 5 | B23: ③ 종합점수·등급 | C23: 다면(상향)평가 점수 · 유효 응답 수 · 공통평가 점수 · 부서장 여부를 입력한다. B3의 배점 스위치로 개정 14 채택안(75:20:5)과 현행(85:10:5)을 전환한다.
A24: 6 | B24: ③ 등급 확인 | C24: 등급 정원은 직급별 전사 단위로 최대잔여법에 따라 자동 배정된다(시트 하단 정원 블록). 부서 단위 배정이 아니다(규칙 제26조①).
A25: 7 | B25: ⑤ 검증 | C25: 모든 판정이 PASS인지 확인한다. 종합 판정 셀 하나만 봐도 된다.
A26: 8 | B26: 인쇄 · 제출 | C26: 사측 설명 시에는 ⑤ 검증 → ⑥ 예제 → ④ s(n) 표 순서로 보인다. ④는 「그 표는 어디서 나왔는가」에 대한 답이다.
A28: 시트 구성
A29: 시트 | B29: 내용
A30: 사용법 | B30: 이 시트. 색 구분과 작업 순서.
A31: 평가군 계산 | B31: ★ 주 시트. 평가군 구성 · 순위 · s(n) · z · 보정점수 · 제7호 조정. 실무자는 여기서만 작업한다.
A32: 종합점수·등급 | B32: 1차·2차 보정점수와 다면·공통을 합산한 종합점수, 직급별 등급(최대잔여법)과 평정점([별표 7]).
A33: s(n) 표 | B33: n = 2~40 의 z값과 그 표준편차를 NORM.S.INV · STDEVP 로 계산한다. 「s(n) 표는 어디서 나왔는가」에 대한 답.
A34: 검증 | B34: ★ 사측 설득의 핵심. 평균 80·표준편차 7 달성, ÷s(n) 없을 때의 미달, 조정 합계 0, 순위 보존, 절단 0건, 정원 합계를 PASS/FAIL로 자동 판정한다.
A35: 예제 | B35: 예제 A(극단 성향) · B(제5호) · C(균등 성향)를 수식으로 재현한다.
A36: MIS 요구사항 | B36: 내부경영정보시스템 근무평정 모듈에 요청할 기능 명세(화면·입력·계산·검증·출력·권한).
A37: 근거 조문 | B37: 각 계산이 개정안의 어느 조문에 대응하는지 정리한 표.
A39: 산식 요약 — [별표 9] 제3호
A40: z = Φ⁻¹( (r − 0.375) ÷ (n + 0.25) ) 보정점수 = 80 + 7 × z ÷ s(n)
A41: r = 평가군 내 순위(최저점자 1위 · 최고점자 n위) · n = 평가군 인원 · s(n) = 인원 n일 때 z값들의 표준편차(17명 이상은 1). 60점 미만은 60점, 100점 초과는 100점으로 하고 소수점 셋째자리에서 반올림한다. 엑셀에서는 =ROUND(MEDIAN(60,80+7*NORM.S.INV((r-0.375)/(n+0.25))/s,100),3) 이다.
A42: 조합이 먼저 밝히는 논점
A43: 제3호 후단의 「17명 이상은 s(n) = 1로 본다」를 그대로 적용하면 17명 이상 평가군의 표준편차가 7.00에 미달한다(n=17 → 6.51 · n=30 → 6.70 · n=40 → 6.76). 1차 평가군(부서 단위 3~16명)은 영향이 없으나 2차 평가군(본부 단위)은 통상 17명 이상이므로 영향을 받는다. 이 계산서는 규정 문언대로 구현하고 그 결과를 ⑤ 검증 시트 1-2절에 수치로 드러내 두었다. 해소하려면 제3호 후단을 삭제하고 s(n) 표를 인원 구간 전체로 확대하면 되며, ④ 시트가 이미 n = 40까지 계산해 두었다.

Sheet s(n) 표
A1: ④ s(n) 표 — 인원 n일 때 Blom z값들의 표준편차
A2: [별표 9] 제3호의 s(n)이다. z가 곧 정규 순서통계량 근사값이므로 s(n)은 그 모표준편차(STDEVP)다. s(n)은 해당 평가군 z값들의 표준편차(=STDEVP)다. 인원이 많아도 1로 보지 아니한다.
A3: 각 셀은 =NORM.S.INV((i−0.375)/(n+0.25)) 이다. 값을 적어 둔 것이 아니라 수식으로 계산한다.
A4: n | B4: 1 | C4: 2 | D4: 3 | E4: 4 | F4: 5 | G4: 6 | H4: 7 | I4: 8 | J4: 9 | K4: 10 | L4: 11 | M4: 12 | N4: 13 | O4: 14 | P4: 15 | Q4: 16 | R4: 17 | S4: 18 | T4: 19 | U4: 20 | V4: 21 | W4: 22 | X4: 23 | Y4: 24 | Z4: 25 | AA4: 26 | AB4: 27 | AC4: 28 | AD4: 29 | AE4: 30 | AF4: 31 | AG4: 32 | AH4: 33 | AI4: 34 | AJ4: 35 | AK4: 36 | AL4: 37 | AM4: 38 | AN4: 39 | AO4: 40 | AP4: s(n) 계산값 = STDEVP | AQ4: 규정 적용값 | AR4: [별표 9] 표 참고값 | AS4: 일치 판정
A5: 2 | B5: =IF(B$4<=$A5,NORM.S.INV((B$4-0.375)/($A5+0.25)),"") | C5: =IF(C$4<=$A5,NORM.S.INV((C$4-0.375)/($A5+0.25)),"") | D5: =IF(D$4<=$A5,NORM.S.INV((D$4-0.375)/($A5+0.25)),"") | E5: =IF(E$4<=$A5,NORM.S.INV((E$4-0.375)/($A5+0.25)),"") | F5: =IF(F$4<=$A5,NORM.S.INV((F$4-0.375)/($A5+0.25)),"") | G5: =IF(G$4<=$A5,NORM.S.INV((G$4-0.375)/($A5+0.25)),"") | H5: =IF(H$4<=$A5,NORM.S.INV((H$4-0.375)/($A5+0.25)),"") | I5: =IF(I$4<=$A5,NORM.S.INV((I$4-0.375)/($A5+0.25)),"") | ... AO5: =IF(AO$4<=$A5,NORM.S.INV((AO$4-0.375)/($A5+0.25)),"") | AP5: =STDEVP($B5:$AO5) | AQ5: =AP5 | AR5: 0.5895 | AS5: =IF(ROUND(AP5,4)=AR5,"PASS","FAIL")
A6: 3 | B6: =IF(B$4<=$A6,NORM.S.INV((B$4-0.375)/($A6+0.25)),"") | C6: =IF(C$4<=$A6,NORM.S.INV((C$4-0.375)/($A6+0.25)),"") | D6: =IF(D$4<=$A6,NORM.S.INV((D$4-0.375)/($A6+0.25)),"") | E6: =IF(E$4<=$A6,NORM.S.INV((E$4-0.375)/($A6+0.25)),"") | F6: =IF(F$4<=$A6,NORM.S.INV((F$4-0.375)/($A6+0.25)),"") | G6: =IF(G$4<=$A6,NORM.S.INV((G$4-0.375)/($A6+0.25)),"") | H6: =IF(H$4<=$A6,NORM.S.INV((H$4-0.375)/($A6+0.25)),"") | I6: =IF(I$4<=$A6,NORM.S.INV((I$4-0.375)/($A6+0.25)),"") | ... AO6: =IF(AO$4<=$A6,NORM.S.INV((AO$4-0.375)/($A6+0.25)),"") | AP6: =STDEVP($B6:$AO6) | AQ6: =AP6 | AR6: 0.7099 | AS6: =IF(ROUND(AP6,4)=AR6,"PASS","FAIL")
A7: 4 | B7: =IF(B$4<=$A7,NORM.S.INV((B$4-0.375)/($A7+0.25)),"") | C7: =IF(C$4<=$A7,NORM.S.INV((C$4-0.375)/($A7+0.25)),"") | D7: =IF(D$4<=$A7,NORM.S.INV((D$4-0.375)/($A7+0.25)),"") | E7: =IF(E$4<=$A7,NORM.S.INV((E$4-0.375)/($A7+0.25)),"") | F7: =IF(F$4<=$A7,NORM.S.INV((F$4-0.375)/($A7+0.25)),"") | G7: =IF(G$4<=$A7,NORM.S.INV((G$4-0.375)/($A7+0.25)),"") | H7: =IF(H$4<=$A7,NORM.S.INV((H$4-0.375)/($A7+0.25)),"") | I7: =IF(I$4<=$A7,NORM.S.INV((I$4-0.375)/($A7+0.25)),"") | ... AO7: =IF(AO$4<=$A7,NORM.S.INV((AO$4-0.375)/($A7+0.25)),"") | AP7: =STDEVP($B7:$AO7) | AQ7: =AP7 | AR7: 0.7714 | AS7: =IF(ROUND(AP7,4)=AR7,"PASS","FAIL")
A8: 5 | B8: =IF(B$4<=$A8,NORM.S.INV((B$4-0.375)/($A8+0.25)),"") | C8: =IF(C$4<=$A8,NORM.S.INV((C$4-0.375)/($A8+0.25)),"") | D8: =IF(D$4<=$A8,NORM.S.INV((D$4-0.375)/($A8+0.25)),"") | E8: =IF(E$4<=$A8,NORM.S.INV((E$4-0.375)/($A8+0.25)),"") | F8: =IF(F$4<=$A8,NORM.S.INV((F$4-0.375)/($A8+0.25)),"") | G8: =IF(G$4<=$A8,NORM.S.INV((G$4-0.375)/($A8+0.25)),"") | H8: =IF(H$4<=$A8,NORM.S.INV((H$4-0.375)/($A8+0.25)),"") | I8: =IF(I$4<=$A8,NORM.S.INV((I$4-0.375)/($A8+0.25)),"") | ... AO8: =IF(AO$4<=$A8,NORM.S.INV((AO$4-0.375)/($A8+0.25)),"") | AP8: =STDEVP($B8:$AO8) | AQ8: =AP8 | AR8: 0.8097 | AS8: =IF(ROUND(AP8,4)=AR8,"PASS","FAIL")
A9: 6 | B9: =IF(B$4<=$A9,NORM.S.INV((B$4-0.375)/($A9+0.25)),"") | C9: =IF(C$4<=$A9,NORM.S.INV((C$4-0.375)/($A9+0.25)),"") | D9: =IF(D$4<=$A9,NORM.S.INV((D$4-0.375)/($A9+0.25)),"") | E9: =IF(E$4<=$A9,NORM.S.INV((E$4-0.375)/($A9+0.25)),"") | F9: =IF(F$4<=$A9,NORM.S.INV((F$4-0.375)/($A9+0.25)),"") | G9: =IF(G$4<=$A9,NORM.S.INV((G$4-0.375)/($A9+0.25)),"") | H9: =IF(H$4<=$A9,NORM.S.INV((H$4-0.375)/($A9+0.25)),"") | I9: =IF(I$4<=$A9,NORM.S.INV((I$4-0.375)/($A9+0.25)),"") | ... AO9: =IF(AO$4<=$A9,NORM.S.INV((AO$4-0.375)/($A9+0.25)),"") | AP9: =STDEVP($B9:$AO9) | AQ9: =AP9 | AR9: 0.8361 | AS9: =IF(ROUND(AP9,4)=AR9,"PASS","FAIL")
A10: 7 | B10: =IF(B$4<=$A10,NORM.S.INV((B$4-0.375)/($A10+0.25)),"") | C10: =IF(C$4<=$A10,NORM.S.INV((C$4-0.375)/($A10+0.25)),"") | D10: =IF(D$4<=$A10,NORM.S.INV((D$4-0.375)/($A10+0.25)),"") | E10: =IF(E$4<=$A10,NORM.S.INV((E$4-0.375)/($A10+0.25)),"") | F10: =IF(F$4<=$A10,NORM.S.INV((F$4-0.375)/($A10+0.25)),"") | G10: =IF(G$4<=$A10,NORM.S.INV((G$4-0.375)/($A10+0.25)),"") | H10: =IF(H$4<=$A10,NORM.S.INV((H$4-0.375)/($A10+0.25)),"") | I10: =IF(I$4<=$A10,NORM.S.INV((I$4-0.375)/($A10+0.25)),"") | ... AO10: =IF(AO$4<=$A10,NORM.S.INV((AO$4-0.375)/($A10+0.25)),"") | AP10: =STDEVP($B10:$AO10) | AQ10: =AP10 | AR10: 0.8555 | AS10: =IF(ROUND(AP10,4)=AR10,"PASS","FAIL")
A11: 8 | B11: =IF(B$4<=$A11,NORM.S.INV((B$4-0.375)/($A11+0.25)),"") | C11: =IF(C$4<=$A11,NORM.S.INV((C$4-0.375)/($A11+0.25)),"") | D11: =IF(D$4<=$A11,NORM.S.INV((D$4-0.375)/($A11+0.25)),"") | E11: =IF(E$4<=$A11,NORM.S.INV((E$4-0.375)/($A11+0.25)),"") | F11: =IF(F$4<=$A11,NORM.S.INV((F$4-0.375)/($A11+0.25)),"") | G11: =IF(G$4<=$A11,NORM.S.INV((G$4-0.375)/($A11+0.25)),"") | H11: =IF(H$4<=$A11,NORM.S.INV((H$4-0.375)/($A11+0.25)),"") | I11: =IF(I$4<=$A11,NORM.S.INV((I$4-0.375)/($A11+0.25)),"") | ... AO11: =IF(AO$4<=$A11,NORM.S.INV((AO$4-0.375)/($A11+0.25)),"") | AP11: =STDEVP($B11:$AO11) | AQ11: =AP11 | AR11: 0.8704 | AS11: =IF(ROUND(AP11,4)=AR11,"PASS","FAIL")
A12: 9 | B12: =IF(B$4<=$A12,NORM.S.INV((B$4-0.375)/($A12+0.25)),"") | C12: =IF(C$4<=$A12,NORM.S.INV((C$4-0.375)/($A12+0.25)),"") | D12: =IF(D$4<=$A12,NORM.S.INV((D$4-0.375)/($A12+0.25)),"") | E12: =IF(E$4<=$A12,NORM.S.INV((E$4-0.375)/($A12+0.25)),"") | F12: =IF(F$4<=$A12,NORM.S.INV((F$4-0.375)/($A12+0.25)),"") | G12: =IF(G$4<=$A12,NORM.S.INV((G$4-0.375)/($A12+0.25)),"") | H12: =IF(H$4<=$A12,NORM.S.INV((H$4-0.375)/($A12+0.25)),"") | I12: =IF(I$4<=$A12,NORM.S.INV((I$4-0.375)/($A12+0.25)),"") | ... AO12: =IF(AO$4<=$A12,NORM.S.INV((AO$4-0.375)/($A12+0.25)),"") | AP12: =STDEVP($B12:$AO12) | AQ12: =AP12 | AR12: 0.8823 | AS12: =IF(ROUND(AP12,4)=AR12,"PASS","FAIL")
A13: 10 | B13: =IF(B$4<=$A13,NORM.S.INV((B$4-0.375)/($A13+0.25)),"") | C13: =IF(C$4<=$A13,NORM.S.INV((C$4-0.375)/($A13+0.25)),"") | D13: =IF(D$4<=$A13,NORM.S.INV((D$4-0.375)/($A13+0.25)),"") | E13: =IF(E$4<=$A13,NORM.S.INV((E$4-0.375)/($A13+0.25)),"") | F13: =IF(F$4<=$A13,NORM.S.INV((F$4-0.375)/($A13+0.25)),"") | G13: =IF(G$4<=$A13,NORM.S.INV((G$4-0.375)/($A13+0.25)),"") | H13: =IF(H$4<=$A13,NORM.S.INV((H$4-0.375)/($A13+0.25)),"") | I13: =IF(I$4<=$A13,NORM.S.INV((I$4-0.375)/($A13+0.25)),"") | ... AO13: =IF(AO$4<=$A13,NORM.S.INV((AO$4-0.375)/($A13+0.25)),"") | AP13: =STDEVP($B13:$AO13) | AQ13: =AP13 | AR13: 0.892 | AS13: =IF(ROUND(AP13,4)=AR13,"PASS","FAIL")
A14: 11 | B14: =IF(B$4<=$A14,NORM.S.INV((B$4-0.375)/($A14+0.25)),"") | C14: =IF(C$4<=$A14,NORM.S.INV((C$4-0.375)/($A14+0.25)),"") | D14: =IF(D$4<=$A14,NORM.S.INV((D$4-0.375)/($A14+0.25)),"") | E14: =IF(E$4<=$A14,NORM.S.INV((E$4-0.375)/($A14+0.25)),"") | F14: =IF(F$4<=$A14,NORM.S.INV((F$4-0.375)/($A14+0.25)),"") | G14: =IF(G$4<=$A14,NORM.S.INV((G$4-0.375)/($A14+0.25)),"") | H14: =IF(H$4<=$A14,NORM.S.INV((H$4-0.375)/($A14+0.25)),"") | I14: =IF(I$4<=$A14,NORM.S.INV((I$4-0.375)/($A14+0.25)),"") | ... AO14: =IF(AO$4<=$A14,NORM.S.INV((AO$4-0.375)/($A14+0.25)),"") | AP14: =STDEVP($B14:$AO14) | AQ14: =AP14 | AR14: 0.9001 | AS14: =IF(ROUND(AP14,4)=AR14,"PASS","FAIL")
A15: 12 | B15: =IF(B$4<=$A15,NORM.S.INV((B$4-0.375)/($A15+0.25)),"") | C15: =IF(C$4<=$A15,NORM.S.INV((C$4-0.375)/($A15+0.25)),"") | D15: =IF(D$4<=$A15,NORM.S.INV((D$4-0.375)/($A15+0.25)),"") | E15: =IF(E$4<=$A15,NORM.S.INV((E$4-0.375)/($A15+0.25)),"") | F15: =IF(F$4<=$A15,NORM.S.INV((F$4-0.375)/($A15+0.25)),"") | G15: =IF(G$4<=$A15,NORM.S.INV((G$4-0.375)/($A15+0.25)),"") | H15: =IF(H$4<=$A15,NORM.S.INV((H$4-0.375)/($A15+0.25)),"") | I15: =IF(I$4<=$A15,NORM.S.INV((I$4-0.375)/($A15+0.25)),"") | ... AO15: =IF(AO$4<=$A15,NORM.S.INV((AO$4-0.375)/($A15+0.25)),"") | AP15: =STDEVP($B15:$AO15) | AQ15: =AP15 | AR15: 0.907 | AS15: =IF(ROUND(AP15,4)=AR15,"PASS","FAIL")
A16: 13 | B16: =IF(B$4<=$A16,NORM.S.INV((B$4-0.375)/($A16+0.25)),"") | C16: =IF(C$4<=$A16,NORM.S.INV((C$4-0.375)/($A16+0.25)),"") | D16: =IF(D$4<=$A16,NORM.S.INV((D$4-0.375)/($A16+0.25)),"") | E16: =IF(E$4<=$A16,NORM.S.INV((E$4-0.375)/($A16+0.25)),"") | F16: =IF(F$4<=$A16,NORM.S.INV((F$4-0.375)/($A16+0.25)),"") | G16: =IF(G$4<=$A16,NORM.S.INV((G$4-0.375)/($A16+0.25)),"") | H16: =IF(H$4<=$A16,NORM.S.INV((H$4-0.375)/($A16+0.25)),"") | I16: =IF(I$4<=$A16,NORM.S.INV((I$4-0.375)/($A16+0.25)),"") | ... AO16: =IF(AO$4<=$A16,NORM.S.INV((AO$4-0.375)/($A16+0.25)),"") | AP16: =STDEVP($B16:$AO16) | AQ16: =AP16 | AR16: 0.9129 | AS16: =IF(ROUND(AP16,4)=AR16,"PASS","FAIL")
... A19: 16 | B19: =IF(B$4<=$A19,NORM.S.INV((B$4-0.375)/($A19+0.25)),"") | C19: =IF(C$4<=$A19,NORM.S.INV((C$4-0.375)/($A19+0.25)),"") | D19: =IF(D$4<=$A19,NORM.S.INV((D$4-0.375)/($A19+0.25)),"") | E19: =IF(E$4<=$A19,NORM.S.INV((E$4-0.375)/($A19+0.25)),"") | F19: =IF(F$4<=$A19,NORM.S.INV((F$4-0.375)/($A19+0.25)),"") | G19: =IF(G$4<=$A19,NORM.S.INV((G$4-0.375)/($A19+0.25)),"") | H19: =IF(H$4<=$A19,NORM.S.INV((H$4-0.375)/($A19+0.25)),"") | I19: =IF(I$4<=$A19,NORM.S.INV((I$4-0.375)/($A19+0.25)),"") | ... AO19: =IF(AO$4<=$A19,NORM.S.INV((AO$4-0.375)/($A19+0.25)),"") | AP19: =STDEVP($B19:$AO19) | AQ19: =AP19 | AR19: 0.9266 | AS19: =IF(ROUND(AP19,4)=AR19,"PASS","FAIL")
A20: 17 | B20: =IF(B$4<=$A20,NORM.S.INV((B$4-0.375)/($A20+0.25)),"") | C20: =IF(C$4<=$A20,NORM.S.INV((C$4-0.375)/($A20+0.25)),"") | D20: =IF(D$4<=$A20,NORM.S.INV((D$4-0.375)/($A20+0.25)),"") | E20: =IF(E$4<=$A20,NORM.S.INV((E$4-0.375)/($A20+0.25)),"") | F20: =IF(F$4<=$A20,NORM.S.INV((F$4-0.375)/($A20+0.25)),"") | G20: =IF(G$4<=$A20,NORM.S.INV((G$4-0.375)/($A20+0.25)),"") | H20: =IF(H$4<=$A20,NORM.S.INV((H$4-0.375)/($A20+0.25)),"") | I20: =IF(I$4<=$A20,NORM.S.INV((I$4-0.375)/($A20+0.25)),"") | ... AO20: =IF(AO$4<=$A20,NORM.S.INV((AO$4-0.375)/($A20+0.25)),"") | AP20: =STDEVP($B20:$AO20) | AQ20: =AP20 | AR20: — | AS20: 참고값 없음 (s=1 적용)
A21: 18 | B21: =IF(B$4<=$A21,NORM.S.INV((B$4-0.375)/($A21+0.25)),"") | C21: =IF(C$4<=$A21,NORM.S.INV((C$4-0.375)/($A21+0.25)),"") | D21: =IF(D$4<=$A21,NORM.S.INV((D$4-0.375)/($A21+0.25)),"") | E21: =IF(E$4<=$A21,NORM.S.INV((E$4-0.375)/($A21+0.25)),"") | F21: =IF(F$4<=$A21,NORM.S.INV((F$4-0.375)/($A21+0.25)),"") | G21: =IF(G$4<=$A21,NORM.S.INV((G$4-0.375)/($A21+0.25)),"") | H21: =IF(H$4<=$A21,NORM.S.INV((H$4-0.375)/($A21+0.25)),"") | I21: =IF(I$4<=$A21,NORM.S.INV((I$4-0.375)/($A21+0.25)),"") | ... AO21: =IF(AO$4<=$A21,NORM.S.INV((AO$4-0.375)/($A21+0.25)),"") | AP21: =STDEVP($B21:$AO21) | AQ21: =AP21 | AR21: — | AS21: 참고값 없음 (s=1 적용)
A22: 19 | B22: =IF(B$4<=$A22,NORM.S.INV((B$4-0.375)/($A22+0.25)),"") | C22: =IF(C$4<=$A22,NORM.S.INV((C$4-0.375)/($A22+0.25)),"") | D22: =IF(D$4<=$A22,NORM.S.INV((D$4-0.375)/($A22+0.25)),"") | E22: =IF(E$4<=$A22,NORM.S.INV((E$4-0.375)/($A22+0.25)),"") | F22: =IF(F$4<=$A22,NORM.S.INV((F$4-0.375)/($A22+0.25)),"") | G22: =IF(G$4<=$A22,NORM.S.INV((G$4-0.375)/($A22+0.25)),"") | H22: =IF(H$4<=$A22,NORM.S.INV((H$4-0.375)/($A22+0.25)),"") | I22: =IF(I$4<=$A22,NORM.S.INV((I$4-0.375)/($A22+0.25)),"") | ... AO22: =IF(AO$4<=$A22,NORM.S.INV((AO$4-0.375)/($A22+0.25)),"") | AP22: =STDEVP($B22:$AO22) | AQ22: =AP22 | AR22: — | AS22: 참고값 없음 (s=1 적용)
A23: 20 | B23: =IF(B$4<=$A23,NORM.S.INV((B$4-0.375)/($A23+0.25)),"") | C23: =IF(C$4<=$A23,NORM.S.INV((C$4-0.375)/($A23+0.25)),"") | D23: =IF(D$4<=$A23,NORM.S.INV((D$4-0.375)/($A23+0.25)),"") | E23: =IF(E$4<=$A23,NORM.S.INV((E$4-0.375)/($A23+0.25)),"") | F23: =IF(F$4<=$A23,NORM.S.INV((F$4-0.375)/($A23+0.25)),"") | G23: =IF(G$4<=$A23,NORM.S.INV((G$4-0.375)/($A23+0.25)),"") | H23: =IF(H$4<=$A23,NORM.S.INV((H$4-0.375)/($A23+0.25)),"") | I23: =IF(I$4<=$A23,NORM.S.INV((I$4-0.375)/($A23+0.25)),"") | ... AO23: =IF(AO$4<=$A23,NORM.S.INV((AO$4-0.375)/($A23+0.25)),"") | AP23: =STDEVP($B23:$AO23) | AQ23: =AP23 | AR23: — | AS23: 참고값 없음 (s=1 적용)
A24: 21 | B24: =IF(B$4<=$A24,NORM.S.INV((B$4-0.375)/($A24+0.25)),"") | C24: =IF(C$4<=$A24,NORM.S.INV((C$4-0.375)/($A24+0.25)),"") | D24: =IF(D$4<=$A24,NORM.S.INV((D$4-0.375)/($A24+0.25)),"") | E24: =IF(E$4<=$A24,NORM.S.INV((E$4-0.375)/($A24+0.25)),"") | F24: =IF(F$4<=$A24,NORM.S.INV((F$4-0.375)/($A24+0.25)),"") | G24: =IF(G$4<=$A24,NORM.S.INV((G$4-0.375)/($A24+0.25)),"") | H24: =IF(H$4<=$A24,NORM.S.INV((H$4-0.375)/($A24+0.25)),"") | I24: =IF(I$4<=$A24,NORM.S.INV((I$4-0.375)/($A24+0.25)),"") | ... AO24: =IF(AO$4<=$A24,NORM.S.INV((AO$4-0.375)/($A24+0.25)),"") | AP24: =STDEVP($B24:$AO24) | AQ24: =AP24 | AR24: — | AS24: 참고값 없음 (s=1 적용)
A25: 22 | B25: =IF(B$4<=$A25,NORM.S.INV((B$4-0.375)/($A25+0.25)),"") | C25: =IF(C$4<=$A25,NORM.S.INV((C$4-0.375)/($A25+0.25)),"") | D25: =IF(D$4<=$A25,NORM.S.INV((D$4-0.375)/($A25+0.25)),"") | E25: =IF(E$4<=$A25,NORM.S.INV((E$4-0.375)/($A25+0.25)),"") | F25: =IF(F$4<=$A25,NORM.S.INV((F$4-0.375)/($A25+0.25)),"") | G25: =IF(G$4<=$A25,NORM.S.INV((G$4-0.375)/($A25+0.25)),"") | H25: =IF(H$4<=$A25,NORM.S.INV((H$4-0.375)/($A25+0.25)),"") | I25: =IF(I$4<=$A25,NORM.S.INV((I$4-0.375)/($A25+0.25)),"") | ... AO25: =IF(AO$4<=$A25,NORM.S.INV((AO$4-0.375)/($A25+0.25)),"") | AP25: =STDEVP($B25:$AO25) | AQ25: =AP25 | AR25: — | AS25: 참고값 없음 (s=1 적용)
A26: 23 | B26: =IF(B$4<=$A26,NORM.S.INV((B$4-0.375)/($A26+0.25)),"") | C26: =IF(C$4<=$A26,NORM.S.INV((C$4-0.375)/($A26+0.25)),"") | D26: =IF(D$4<=$A26,NORM.S.INV((D$4-0.375)/($A26+0.25)),"") | E26: =IF(E$4<=$A26,NORM.S.INV((E$4-0.375)/($A26+0.25)),"") | F26: =IF(F$4<=$A26,NORM.S.INV((F$4-0.375)/($A26+0.25)),"") | G26: =IF(G$4<=$A26,NORM.S.INV((G$4-0.375)/($A26+0.25)),"") | H26: =IF(H$4<=$A26,NORM.S.INV((H$4-0.375)/($A26+0.25)),"") | I26: =IF(I$4<=$A26,NORM.S.INV((I$4-0.375)/($A26+0.25)),"") | ... AO26: =IF(AO$4<=$A26,NORM.S.INV((AO$4-0.375)/($A26+0.25)),"") | AP26: =STDEVP($B26:$AO26) | AQ26: =AP26 | AR26: — | AS26: 참고값 없음 (s=1 적용)
A27: 24 | B27: =IF(B$4<=$A27,NORM.S.INV((B$4-0.375)/($A27+0.25)),"") | C27: =IF(C$4<=$A27,NORM.S.INV((C$4-0.375)/($A27+0.25)),"") | D27: =IF(D$4<=$A27,NORM.S.INV((D$4-0.375)/($A27+0.25)),"") | E27: =IF(E$4<=$A27,NORM.S.INV((E$4-0.375)/($A27+0.25)),"") | F27: =IF(F$4<=$A27,NORM.S.INV((F$4-0.375)/($A27+0.25)),"") | G27: =IF(G$4<=$A27,NORM.S.INV((G$4-0.375)/($A27+0.25)),"") | H27: =IF(H$4<=$A27,NORM.S.INV((H$4-0.375)/($A27+0.25)),"") | I27: =IF(I$4<=$A27,NORM.S.INV((I$4-0.375)/($A27+0.25)),"") | ... AO27: =IF(AO$4<=$A27,NORM.S.INV((AO$4-0.375)/($A27+0.25)),"") | AP27: =STDEVP($B27:$AO27) | AQ27: =AP27 | AR27: — | AS27: 참고값 없음 (s=1 적용)
A28: 25 | B28: =IF(B$4<=$A28,NORM.S.INV((B$4-0.375)/($A28+0.25)),"") | C28: =IF(C$4<=$A28,NORM.S.INV((C$4-0.375)/($A28+0.25)),"") | D28: =IF(D$4<=$A28,NORM.S.INV((D$4-0.375)/($A28+0.25)),"") | E28: =IF(E$4<=$A28,NORM.S.INV((E$4-0.375)/($A28+0.25)),"") | F28: =IF(F$4<=$A28,NORM.S.INV((F$4-0.375)/($A28+0.25)),"") | G28: =IF(G$4<=$A28,NORM.S.INV((G$4-0.375)/($A28+0.25)),"") | H28: =IF(H$4<=$A28,NORM.S.INV((H$4-0.375)/($A28+0.25)),"") | I28: =IF(I$4<=$A28,NORM.S.INV((I$4-0.375)/($A28+0.25)),"") | ... AO28: =IF(AO$4<=$A28,NORM.S.INV((AO$4-0.375)/($A28+0.25)),"") | AP28: =STDEVP($B28:$AO28) | AQ28: =AP28 | AR28: — | AS28: 참고값 없음 (s=1 적용)
A29: 26 | B29: =IF(B$4<=$A29,NORM.S.INV((B$4-0.375)/($A29+0.25)),"") | C29: =IF(C$4<=$A29,NORM.S.INV((C$4-0.375)/($A29+0.25)),"") | D29: =IF(D$4<=$A29,NORM.S.INV((D$4-0.375)/($A29+0.25)),"") | E29: =IF(E$4<=$A29,NORM.S.INV((E$4-0.375)/($A29+0.25)),"") | F29: =IF(F$4<=$A29,NORM.S.INV((F$4-0.375)/($A29+0.25)),"") | G29: =IF(G$4<=$A29,NORM.S.INV((G$4-0.375)/($A29+0.25)),"") | H29: =IF(H$4<=$A29,NORM.S.INV((H$4-0.375)/($A29+0.25)),"") | I29: =IF(I$4<=$A29,NORM.S.INV((I$4-0.375)/($A29+0.25)),"") | ... AO29: =IF(AO$4<=$A29,NORM.S.INV((AO$4-0.375)/($A29+0.25)),"") | AP29: =STDEVP($B29:$AO29) | AQ29: =AP29 | AR29: — | AS29: 참고값 없음 (s=1 적용)
A30: 27 | B30: =IF(B$4<=$A30,NORM.S.INV((B$4-0.375)/($A30+0.25)),"") | C30: =IF(C$4<=$A30,NORM.S.INV((C$4-0.375)/($A30+0.25)),"") | D30: =IF(D$4<=$A30,NORM.S.INV((D$4-0.375)/($A30+0.25)),"") | E30: =IF(E$4<=$A30,NORM.S.INV((E$4-0.375)/($A30+0.25)),"") | F30: =IF(F$4<=$A30,NORM.S.INV((F$4-0.375)/($A30+0.25)),"") | G30: =IF(G$4<=$A30,NORM.S.INV((G$4-0.375)/($A30+0.25)),"") | H30: =IF(H$4<=$A30,NORM.S.INV((H$4-0.375)/($A30+0.25)),"") | I30: =IF(I$4<=$A30,NORM.S.INV((I$4-0.375)/($A30+0.25)),"") | ... AO30: =IF(AO$4<=$A30,NORM.S.INV((AO$4-0.375)/($A30+0.25)),"") | AP30: =STDEVP($B30:$AO30) | AQ30: =AP30 | AR30: — | AS30: 참고값 없음 (s=1 적용)
A31: 28 | B31: =IF(B$4<=$A31,NORM.S.INV((B$4-0.375)/($A31+0.25)),"") | C31: =IF(C$4<=$A31,NORM.S.INV((C$4-0.375)/($A31+0.25)),"") | D31: =IF(D$4<=$A31,NORM.S.INV((D$4-0.375)/($A31+0.25)),"") | E31: =IF(E$4<=$A31,NORM.S.INV((E$4-0.375)/($A31+0.25)),"") | F31: =IF(F$4<=$A31,NORM.S.INV((F$4-0.375)/($A31+0.25)),"") | G31: =IF(G$4<=$A31,NORM.S.INV((G$4-0.375)/($A31+0.25)),"") | H31: =IF(H$4<=$A31,NORM.S.INV((H$4-0.375)/($A31+0.25)),"") | I31: =IF(I$4<=$A31,NORM.S.INV((I$4-0.375)/($A31+0.25)),"") | ... AO31: =IF(AO$4<=$A31,NORM.S.INV((AO$4-0.375)/($A31+0.25)),"") | AP31: =STDEVP($B31:$AO31) | AQ31: =AP31 | AR31: — | AS31: 참고값 없음 (s=1 적용)
... A43: 40 | B43: =IF(B$4<=$A43,NORM.S.INV((B$4-0.375)/($A43+0.25)),"") | C43: =IF(C$4<=$A43,NORM.S.INV((C$4-0.375)/($A43+0.25)),"") | D43: =IF(D$4<=$A43,NORM.S.INV((D$4-0.375)/($A43+0.25)),"") | E43: =IF(E$4<=$A43,NORM.S.INV((E$4-0.375)/($A43+0.25)),"") | F43: =IF(F$4<=$A43,NORM.S.INV((F$4-0.375)/($A43+0.25)),"") | G43: =IF(G$4<=$A43,NORM.S.INV((G$4-0.375)/($A43+0.25)),"") | H43: =IF(H$4<=$A43,NORM.S.INV((H$4-0.375)/($A43+0.25)),"") | I43: =IF(I$4<=$A43,NORM.S.INV((I$4-0.375)/($A43+0.25)),"") | ... AO43: =IF(AO$4<=$A43,NORM.S.INV((AO$4-0.375)/($A43+0.25)),"") | AP43: =STDEVP($B43:$AO43) | AQ43: =AP43 | AR43: — | AS43: 참고값 없음 (s=1 적용)

Sheet 평가군 계산
A1: ② 평가군 계산 — 개정안 [별표 9] 제1호~제3호·제5호·제7호
A2: 고지 — 이 파일의 모든 인명·점수는 산식 검증을 위한 모의 예시 데이터이며, 창업진흥원의 실제 근무평정 결과가 아니다.
A3: 입력(연노랑): 원점수 · 조정(제7호) · 조정 사유 나머지(연회색)는 모두 자동 계산
A4: 동점 입력 건수 → | C4: =IF(COUNTIF($Q$6:$Q$79,"★동점")=0,"0건 (정상)",COUNTIF($Q$6:$Q$79,"★동점")&"건 ★ 개정 2 위반 — 순위가 중복되어 산식이 깨진다. 원점수를 고쳐라") | L4: 제5호 적용 평가군 수 → | O4: =SUMPRODUCT((COUNTIF($A$6:$A$79,$A$6:$A$79)<6)/COUNTIF($A$6:$A$79,$A$6:$A$79))
A5: 평가군 | B5: 평가자명 | C5: 평가군 구분 | D5: 직급 | E5: 피평가자 | F5: 원점수 | G5: 인원 n | H5: 순위 r (낮은 순 = 1위) | I5: s(n) | J5: p = (r−0.375)/(n+0.25) | K5: z = Φ⁻¹(p) | L5: 보정점수 (제3호) | M5: 적용 기준점수 (제5호 반영) | N5: 조정 (제7호 ±5) | O5: 조정 후 점수 | P5: 조정 사유 | Q5: 동점 경고 | R5: 보정 후 순위 | S5: 순위 보존 검증 | T5: 키 (계산용) | U5: 절단 전 보정점수 (60·100 미적용) | V5: 절단 전 조정 후 점수 (60·100 미적용)
A6: 평가군 1 | B6: 평가자 1 | C6: 1차 | D6: 5급 | E6: 직원01 | F6: 98 | G6: =COUNTIF($A$6:$A$79,$A6) | H6: =RANK.EQ($F6,$F$6:$F$15,1) | I6: =INDEX('s(n) 표'!$AQ$5:$AQ$43,MATCH($G6,'s(n) 표'!$A$5:$A$43,0)) | J6: =($H6-0.375)/($G6+0.25) | K6: =NORM.S.INV($J6) | L6: =IF($G6<6,"",ROUND(MEDIAN(60,80+7*$K6/$I6,100),3)) | M6: =IF($G6>=6,$L6,IFERROR(IF(INDEX($L$6:$L$79,MATCH($E6&"|2차",$T$6:$T$79,0))="",80,INDEX($L$6:$L$79,MATCH($E6&"|2차",$T$6:$T$79,0))),80)) | N6: 5 | O6: =IF($N6="",$M6,ROUND(MEDIAN(60,$M6+$N6,100),3)) | P6: ±5점 조정 — 사유 기재 필수 | Q6: =IF(COUNTIFS($A$6:$A$79,$A6,$F$6:$F$79,$F6)>1,"★동점","") | R6: =IF($L6="","",RANK.EQ($L6,$L$6:$L$15,1)) | S6: =IF($L6="","제5호 - 미실시",IF($R6=$H6,"보존","★불일치")) | T6: =$E6&"|"&$C6 | U6: =IF($G6<6,"",80+7*$K6/$I6) | V6: =IF($N6="",$M6,$M6+$N6)
A7: 평가군 1 | B7: 평가자 1 | C7: 1차 | D7: 5급 | E7: 직원02 | F7: 95 | G7: =COUNTIF($A$6:$A$79,$A7) | H7: =RANK.EQ($F7,$F$6:$F$15,1) | I7: =INDEX('s(n) 표'!$AQ$5:$AQ$43,MATCH($G7,'s(n) 표'!$A$5:$A$43,0)) | J7: =($H7-0.375)/($G7+0.25) | K7: =NORM.S.INV($J7) | L7: =IF($G7<6,"",ROUND(MEDIAN(60,80+7*$K7/$I7,100),3)) | M7: =IF($G7>=6,$L7,IFERROR(IF(INDEX($L$6:$L$79,MATCH($E7&"|2차",$T$6:$T$79,0))="",80,INDEX($L$6:$L$79,MATCH($E7&"|2차",$T$6:$T$79,0))),80)) | N7: 3 | O7: =IF($N7="",$M7,ROUND(MEDIAN(60,$M7+$N7,100),3)) | P7: 조정 사유 기재 | Q7: =IF(COUNTIFS($A$6:$A$79,$A7,$F$6:$F$79,$F7)>1,"★동점","") | R7: =IF($L7="","",RANK.EQ($L7,$L$6:$L$15,1)) | S7: =IF($L7="","제5호 - 미실시",IF($R7=$H7,"보존","★불일치")) | T7: =$E7&"|"&$C7 | U7: =IF($G7<6,"",80+7*$K7/$I7) | V7: =IF($N7="",$M7,$M7+$N7)
A8: 평가군 1 | B8: 평가자 1 | C8: 1차 | D8: 5급 | E8: 직원03 | F8: 92 | G8: =COUNTIF($A$6:$A$79,$A8) | H8: =RANK.EQ($F8,$F$6:$F$15,1) | I8: =INDEX('s(n) 표'!$AQ$5:$AQ$43,MATCH($G8,'s(n) 표'!$A$5:$A$43,0)) | J8: =($H8-0.375)/($G8+0.25) | K8: =NORM.S.INV($J8) | L8: =IF($G8<6,"",ROUND(MEDIAN(60,80+7*$K8/$I8,100),3)) | M8: =IF($G8>=6,$L8,IFERROR(IF(INDEX($L$6:$L$79,MATCH($E8&"|2차",$T$6:$T$79,0))="",80,INDEX($L$6:$L$79,MATCH($E8&"|2차",$T$6:$T$79,0))),80)) | N8: 2 | O8: =IF($N8="",$M8,ROUND(MEDIAN(60,$M8+$N8,100),3)) | P8: 조정 사유 기재 | Q8: =IF(COUNTIFS($A$6:$A$79,$A8,$F$6:$F$79,$F8)>1,"★동점","") | R8: =IF($L8="","",RANK.EQ($L8,$L$6:$L$15,1)) | S8: =IF($L8="","제5호 - 미실시",IF($R8=$H8,"보존","★불일치")) | T8: =$E8&"|"&$C8 | U8: =IF($G8<6,"",80+7*$K8/$I8) | V8: =IF($N8="",$M8,$M8+$N8)
A9: 평가군 1 | B9: 평가자 1 | C9: 1차 | D9: 5급 | E9: 직원04 | F9: 88 | G9: =COUNTIF($A$6:$A$79,$A9) | H9: =RANK.EQ($F9,$F$6:$F$15,1) | I9: =INDEX('s(n) 표'!$AQ$5:$AQ$43,MATCH($G9,'s(n) 표'!$A$5:$A$43,0)) | J9: =($H9-0.375)/($G9+0.25) | K9: =NORM.S.INV($J9) | L9: =IF($G9<6,"",ROUND(MEDIAN(60,80+7*$K9/$I9,100),3)) | M9: =IF($G9>=6,$L9,IFERROR(IF(INDEX($L$6:$L$79,MATCH($E9&"|2차",$T$6:$T$79,0))="",80,INDEX($L$6:$L$79,MATCH($E9&"|2차",$T$6:$T$79,0))),80)) | N9: 1 | O9: =IF($N9="",$M9,ROUND(MEDIAN(60,$M9+$N9,100),3)) | P9: 조정 사유 기재 | Q9: =IF(COUNTIFS($A$6:$A$79,$A9,$F$6:$F$79,$F9)>1,"★동점","") | R9: =IF($L9="","",RANK.EQ($L9,$L$6:$L$15,1)) | S9: =IF($L9="","제5호 - 미실시",IF($R9=$H9,"보존","★불일치")) | T9: =$E9&"|"&$C9 | U9: =IF($G9<6,"",80+7*$K9/$I9) | V9: =IF($N9="",$M9,$M9+$N9)
A10: 평가군 1 | B10: 평가자 1 | C10: 1차 | D10: 5급 | E10: 직원05 | F10: 84 | G10: =COUNTIF($A$6:$A$79,$A10) | H10: =RANK.EQ($F10,$F$6:$F$15,1) | I10: =INDEX('s(n) 표'!$AQ$5:$AQ$43,MATCH($G10,'s(n) 표'!$A$5:$A$43,0)) | J10: =($H10-0.375)/($G10+0.25) | K10: =NORM.S.INV($J10) | L10: =IF($G10<6,"",ROUND(MEDIAN(60,80+7*$K10/$I10,100),3)) | M10: =IF($G10>=6,$L10,IFERROR(IF(INDEX($L$6:$L$79,MATCH($E10&"|2차",$T$6:$T$79,0))="",80,INDEX($L$6:$L$79,MATCH($E10&"|2차",$T$6:$T$79,0))),80)) | N10: 0 | O10: =IF($N10="",$M10,ROUND(MEDIAN(60,$M10+$N10,100),3)) | Q10: =IF(COUNTIFS($A$6:$A$79,$A10,$F$6:$F$79,$F10)>1,"★동점","") | R10: =IF($L10="","",RANK.EQ($L10,$L$6:$L$15,1)) | S10: =IF($L10="","제5호 - 미실시",IF($R10=$H10,"보존","★불일치")) | T10: =$E10&"|"&$C10 | U10: =IF($G10<6,"",80+7*$K10/$I10) | V10: =IF($N10="",$M10,$M10+$N10)
A11: 평가군 1 | B11: 평가자 1 | C11: 1차 | D11: 5급 | E11: 직원06 | F11: 80 | G11: =COUNTIF($A$6:$A$79,$A11) | H11: =RANK.EQ($F11,$F$6:$F$15,1) | I11: =INDEX('s(n) 표'!$AQ$5:$AQ$43,MATCH($G11,'s(n) 표'!$A$5:$A$43,0)) | J11: =($H11-0.375)/($G11+0.25) | K11: =NORM.S.INV($J11) | L11: =IF($G11<6,"",ROUND(MEDIAN(60,80+7*$K11/$I11,100),3)) | M11: =IF($G11>=6,$L11,IFERROR(IF(INDEX($L$6:$L$79,MATCH($E11&"|2차",$T$6:$T$79,0))="",80,INDEX($L$6:$L$79,MATCH($E11&"|2차",$T$6:$T$79,0))),80)) | N11: 0 | O11: =IF($N11="",$M11,ROUND(MEDIAN(60,$M11+$N11,100),3)) | Q11: =IF(COUNTIFS($A$6:$A$79,$A11,$F$6:$F$79,$F11)>1,"★동점","") | R11: =IF($L11="","",RANK.EQ($L11,$L$6:$L$15,1)) | S11: =IF($L11="","제5호 - 미실시",IF($R11=$H11,"보존","★불일치")) | T11: =$E11&"|"&$C11 | U11: =IF($G11<6,"",80+7*$K11/$I11) | V11: =IF($N11="",$M11,$M11+$N11)
A12: 평가군 1 | B12: 평가자 1 | C12: 1차 | D12: 5급 | E12: 직원07 | F12: 76 | G12: =COUNTIF($A$6:$A$79,$A12) | H12: =RANK.EQ($F12,$F$6:$F$15,1) | I12: =INDEX('s(n) 표'!$AQ$5:$AQ$43,MATCH($G12,'s(n) 표'!$A$5:$A$43,0)) | J12: =($H12-0.375)/($G12+0.25) | K12: =NORM.S.INV($J12) | L12: =IF($G12<6,"",ROUND(MEDIAN(60,80+7*$K12/$I12,100),3)) | M12: =IF($G12>=6,$L12,IFERROR(IF(INDEX($L$6:$L$79,MATCH($E12&"|2차",$T$6:$T$79,0))="",80,INDEX($L$6:$L$79,MATCH($E12&"|2차",$T$6:$T$79,0))),80)) | N12: -1 | O12: =IF($N12="",$M12,ROUND(MEDIAN(60,$M12+$N12,100),3)) | P12: 조정 사유 기재 | Q12: =IF(COUNTIFS($A$6:$A$79,$A12,$F$6:$F$79,$F12)>1,"★동점","") | R12: =IF($L12="","",RANK.EQ($L12,$L$6:$L$15,1)) | S12: =IF($L12="","제5호 - 미실시",IF($R12=$H12,"보존","★불일치")) | T12: =$E12&"|"&$C12 | U12: =IF($G12<6,"",80+7*$K12/$I12) | V12: =IF($N12="",$M12,$M12+$N12)
A13: 평가군 1 | B13: 평가자 1 | C13: 1차 | D13: 5급 | E13: 직원08 | F13: 72 | G13: =COUNTIF($A$6:$A$79,$A13) | H13: =RANK.EQ($F13,$F$6:$F$15,1) | I13: =INDEX('s(n) 표'!$AQ$5:$AQ$43,MATCH($G13,'s(n) 표'!$A$5:$A$43,0)) | J13: =($H13-0.375)/($G13+0.25) | K13: =NORM.S.INV($J13) | L13: =IF($G13<6,"",ROUND(MEDIAN(60,80+7*$K13/$I13,100),3)) | M13: =IF($G13>=6,$L13,IFERROR(IF(INDEX($L$6:$L$79,MATCH($E13&"|2차",$T$6:$T$79,0))="",80,INDEX($L$6:$L$79,MATCH($E13&"|2차",$T$6:$T$79,0))),80)) | N13: -2 | O13: =IF($N13="",$M13,ROUND(MEDIAN(60,$M13+$N13,100),3)) | P13: 조정 사유 기재 | Q13: =IF(COUNTIFS($A$6:$A$79,$A13,$F$6:$F$79,$F13)>1,"★동점","") | R13: =IF($L13="","",RANK.EQ($L13,$L$6:$L$15,1)) | S13: =IF($L13="","제5호 - 미실시",IF($R13=$H13,"보존","★불일치")) | T13: =$E13&"|"&$C13 | U13: =IF($G13<6,"",80+7*$K13/$I13) | V13: =IF($N13="",$M13,$M13+$N13)
A14: 평가군 1 | B14: 평가자 1 | C14: 1차 | D14: 5급 | E14: 직원09 | F14: 66 | G14: =COUNTIF($A$6:$A$79,$A14) | H14: =RANK.EQ($F14,$F$6:$F$15,1) | I14: =INDEX('s(n) 표'!$AQ$5:$AQ$43,MATCH($G14,'s(n) 표'!$A$5:$A$43,0)) | J14: =($H14-0.375)/($G14+0.25) | K14: =NORM.S.INV($J14) | L14: =IF($G14<6,"",ROUND(MEDIAN(60,80+7*$K14/$I14,100),3)) | M14: =IF($G14>=6,$L14,IFERROR(IF(INDEX($L$6:$L$79,MATCH($E14&"|2차",$T$6:$T$79,0))="",80,INDEX($L$6:$L$79,MATCH($E14&"|2차",$T$6:$T$79,0))),80)) | N14: -3 | O14: =IF($N14="",$M14,ROUND(MEDIAN(60,$M14+$N14,100),3)) | P14: 조정 사유 기재 | Q14: =IF(COUNTIFS($A$6:$A$79,$A14,$F$6:$F$79,$F14)>1,"★동점","") | R14: =IF($L14="","",RANK.EQ($L14,$L$6:$L$15,1)) | S14: =IF($L14="","제5호 - 미실시",IF($R14=$H14,"보존","★불일치")) | T14: =$E14&"|"&$C14 | U14: =IF($G14<6,"",80+7*$K14/$I14) | V14: =IF($N14="",$M14,$M14+$N14)
A15: 평가군 1 | B15: 평가자 1 | C15: 1차 | D15: 5급 | E15: 직원10 | F15: 60 | G15: =COUNTIF($A$6:$A$79,$A15) | H15: =RANK.EQ($F15,$F$6:$F$15,1) | I15: =INDEX('s(n) 표'!$AQ$5:$AQ$43,MATCH($G15,'s(n) 표'!$A$5:$A$43,0)) | J15: =($H15-0.375)/($G15+0.25) | K15: =NORM.S.INV($J15) | L15: =IF($G15<6,"",ROUND(MEDIAN(60,80+7*$K15/$I15,100),3)) | M15: =IF($G15>=6,$L15,IFERROR(IF(INDEX($L$6:$L$79,MATCH($E15&"|2차",$T$6:$T$79,0))="",80,INDEX($L$6:$L$79,MATCH($E15&"|2차",$T$6:$T$79,0))),80)) | N15: -5 | O15: =IF($N15="",$M15,ROUND(MEDIAN(60,$M15+$N15,100),3)) | P15: ±5점 조정 — 사유 기재 필수 | Q15: =IF(COUNTIFS($A$6:$A$79,$A15,$F$6:$F$79,$F15)>1,"★동점","") | R15: =IF($L15="","",RANK.EQ($L15,$L$6:$L$15,1)) | S15: =IF($L15="","제5호 - 미실시",IF($R15=$H15,"보존","★불일치")) | T15: =$E15&"|"&$C15 | U15: =IF($G15<6,"",80+7*$K15/$I15) | V15: =IF($N15="",$M15,$M15+$N15)
A16: 평가군 2 | B16: 평가자 2 | C16: 1차 | D16: 5급 | E16: 직원11 | F16: 92 | G16: =COUNTIF($A$6:$A$79,$A16) | H16: =RANK.EQ($F16,$F$16:$F$19,1) | I16: =INDEX('s(n) 표'!$AQ$5:$AQ$43,MATCH($G16,'s(n) 표'!$A$5:$A$43,0)) | J16: =($H16-0.375)/($G16+0.25) | K16: =NORM.S.INV($J16) | L16: =IF($G16<6,"",ROUND(MEDIAN(60,80+7*$K16/$I16,100),3)) | M16: =IF($G16>=6,$L16,IFERROR(IF(INDEX($L$6:$L$79,MATCH($E16&"|2차",$T$6:$T$79,0))="",80,INDEX($L$6:$L$79,MATCH($E16&"|2차",$T$6:$T$79,0))),80)) | N16: 4 | O16: =IF($N16="",$M16,ROUND(MEDIAN(60,$M16+$N16,100),3)) | P16: 조정 사유 기재 | Q16: =IF(COUNTIFS($A$6:$A$79,$A16,$F$6:$F$79,$F16)>1,"★동점","") | R16: =IF($L16="","",RANK.EQ($L16,$L$16:$L$19,1)) | S16: =IF($L16="","제5호 - 미실시",IF($R16=$H16,"보존","★불일치")) | T16: =$E16&"|"&$C16 | U16: =IF($G16<6,"",80+7*$K16/$I16) | V16: =IF($N16="",$M16,$M16+$N16)
A17: 평가군 2 | B17: 평가자 2 | C17: 1차 | D17: 5급 | E17: 직원12 | F17: 86 | G17: =COUNTIF($A$6:$A$79,$A17) | H17: =RANK.EQ($F17,$F$16:$F$19,1) | I17: =INDEX('s(n) 표'!$AQ$5:$AQ$43,MATCH($G17,'s(n) 표'!$A$5:$A$43,0)) | J17: =($H17-0.375)/($G17+0.25) | K17: =NORM.S.INV($J17) | L17: =IF($G17<6,"",ROUND(MEDIAN(60,80+7*$K17/$I17,100),3)) | M17: =IF($G17>=6,$L17,IFERROR(IF(INDEX($L$6:$L$79,MATCH($E17&"|2차",$T$6:$T$79,0))="",80,INDEX($L$6:$L$79,MATCH($E17&"|2차",$T$6:$T$79,0))),80)) | N17: 1 | O17: =IF($N17="",$M17,ROUND(MEDIAN(60,$M17+$N17,100),3)) | P17: 조정 사유 기재 | Q17: =IF(COUNTIFS($A$6:$A$79,$A17,$F$6:$F$79,$F17)>1,"★동점","") | R17: =IF($L17="","",RANK.EQ($L17,$L$16:$L$19,1)) | S17: =IF($L17="","제5호 - 미실시",IF($R17=$H17,"보존","★불일치")) | T17: =$E17&"|"&$C17 | U17: =IF($G17<6,"",80+7*$K17/$I17) | V17: =IF($N17="",$M17,$M17+$N17)
A18: 평가군 2 | B18: 평가자 2 | C18: 1차 | D18: 5급 | E18: 직원13 | F18: 78 | G18: =COUNTIF($A$6:$A$79,$A18) | H18: =RANK.EQ($F18,$F$16:$F$19,1) | I18: =INDEX('s(n) 표'!$AQ$5:$AQ$43,MATCH($G18,'s(n) 표'!$A$5:$A$43,0)) | J18: =($H18-0.375)/($G18+0.25) | K18: =NORM.S.INV($J18) | L18: =IF($G18<6,"",ROUND(MEDIAN(60,80+7*$K18/$I18,100),3)) | M18: =IF($G18>=6,$L18,IFERROR(IF(INDEX($L$6:$L$79,MATCH($E18&"|2차",$T$6:$T$79,0))="",80,INDEX($L$6:$L$79,MATCH($E18&"|2차",$T$6:$T$79,0))),80)) | N18: -1 | O18: =IF($N18="",$M18,ROUND(MEDIAN(60,$M18+$N18,100),3)) | P18: 조정 사유 기재 | Q18: =IF(COUNTIFS($A$6:$A$79,$A18,$F$6:$F$79,$F18)>1,"★동점","") | R18: =IF($L18="","",RANK.EQ($L18,$L$16:$L$19,1)) | S18: =IF($L18="","제5호 - 미실시",IF($R18=$H18,"보존","★불일치")) | T18: =$E18&"|"&$C18 | U18: =IF($G18<6,"",80+7*$K18/$I18) | V18: =IF($N18="",$M18,$M18+$N18)
A19: 평가군 2 | B19: 평가자 2 | C19: 1차 | D19: 5급 | E19: 직원14 | F19: 70 | G19: =COUNTIF($A$6:$A$79,$A19) | H19: =RANK.EQ($F19,$F$16:$F$19,1) | I19: =INDEX('s(n) 표'!$AQ$5:$AQ$43,MATCH($G19,'s(n) 표'!$A$5:$A$43,0)) | J19: =($H19-0.375)/($G19+0.25) | K19: =NORM.S.INV($J19) | L19: =IF($G19<6,"",ROUND(MEDIAN(60,80+7*$K19/$I19,100),3)) | M19: =IF($G19>=6,$L19,IFERROR(IF(INDEX($L$6:$L$79,MATCH($E19&"|2차",$T$6:$T$79,0))="",80,INDEX($L$6:$L$79,MATCH($E19&"|2차",$T$6:$T$79,0))),80)) | N19: -4 | O19: =IF($N19="",$M19,ROUND(MEDIAN(60,$M19+$N19,100),3)) | P19: 조정 사유 기재 | Q19: =IF(COUNTIFS($A$6:$A$79,$A19,$F$6:$F$79,$F19)>1,"★동점","") | R19: =IF($L19="","",RANK.EQ($L19,$L$16:$L$19,1)) | S19: =IF($L19="","제5호 - 미실시",IF($R19=$H19,"보존","★불일치")) | T19: =$E19&"|"&$C19 | U19: =IF($G19<6,"",80+7*$K19/$I19) | V19: =IF($N19="",$M19,$M19+$N19)
A20: 평가군 3 | B20: 평가자 3 | C20: 1차 | D20: 5급 | E20: 직원15 | F20: 78 | G20: =COUNTIF($A$6:$A$79,$A20) | H20: =RANK.EQ($F20,$F$20:$F$35,1) | I20: =INDEX('s(n) 표'!$AQ$5:$AQ$43,MATCH($G20,'s(n) 표'!$A$5:$A$43,0)) | J20: =($H20-0.375)/($G20+0.25) | K20: =NORM.S.INV($J20) | L20: =IF($G20<6,"",ROUND(MEDIAN(60,80+7*$K20/$I20,100),3)) | M20: =IF($G20>=6,$L20,IFERROR(IF(INDEX($L$6:$L$79,MATCH($E20&"|2차",$T$6:$T$79,0))="",80,INDEX($L$6:$L$79,MATCH($E20&"|2차",$T$6:$T$79,0))),80)) | N20: 0 | O20: =IF($N20="",$M20,ROUND(MEDIAN(60,$M20+$N20,100),3)) | Q20: =IF(COUNTIFS($A$6:$A$79,$A20,$F$6:$F$79,$F20)>1,"★동점","") | R20: =IF($L20="","",RANK.EQ($L20,$L$20:$L$35,1)) | S20: =IF($L20="","제5호 - 미실시",IF($R20=$H20,"보존","★불일치")) | T20: =$E20&"|"&$C20 | U20: =IF($G20<6,"",80+7*$K20/$I20) | V20: =IF($N20="",$M20,$M20+$N20)
A21: 평가군 3 | B21: 평가자 3 | C21: 1차 | D21: 5급 | E21: 직원16 | F21: 78.1 | G21: =COUNTIF($A$6:$A$79,$A21) | H21: =RANK.EQ($F21,$F$20:$F$35,1) | I21: =INDEX('s(n) 표'!$AQ$5:$AQ$43,MATCH($G21,'s(n) 표'!$A$5:$A$43,0)) | J21: =($H21-0.375)/($G21+0.25) | K21: =NORM.S.INV($J21) | L21: =IF($G21<6,"",ROUND(MEDIAN(60,80+7*$K21/$I21,100),3)) | M21: =IF($G21>=6,$L21,IFERROR(IF(INDEX($L$6:$L$79,MATCH($E21&"|2차",$T$6:$T$79,0))="",80,INDEX($L$6:$L$79,MATCH($E21&"|2차",$T$6:$T$79,0))),80)) | N21: 0 | O21: =IF($N21="",$M21,ROUND(MEDIAN(60,$M21+$N21,100),3)) | Q21: =IF(COUNTIFS($A$6:$A$79,$A21,$F$6:$F$79,$F21)>1,"★동점","") | R21: =IF($L21="","",RANK.EQ($L21,$L$20:$L$35,1)) | S21: =IF($L21="","제5호 - 미실시",IF($R21=$H21,"보존","★불일치")) | T21: =$E21&"|"&$C21 | U21: =IF($G21<6,"",80+7*$K21/$I21) | V21: =IF($N21="",$M21,$M21+$N21)
A22: 평가군 3 | B22: 평가자 3 | C22: 1차 | D22: 5급 | E22: 직원17 | F22: 78.2 | G22: =COUNTIF($A$6:$A$79,$A22) | H22: =RANK.EQ($F22,$F$20:$F$35,1) | I22: =INDEX('s(n) 표'!$AQ$5:$AQ$43,MATCH($G22,'s(n) 표'!$A$5:$A$43,0)) | J22: =($H22-0.375)/($G22+0.25) | K22: =NORM.S.INV($J22) | L22: =IF($G22<6,"",ROUND(MEDIAN(60,80+7*$K22/$I22,100),3)) | M22: =IF($G22>=6,$L22,IFERROR(IF(INDEX($L$6:$L$79,MATCH($E22&"|2차",$T$6:$T$79,0))="",80,INDEX($L$6:$L$79,MATCH($E22&"|2차",$T$6:$T$79,0))),80)) | N22: 0 | O22: =IF($N22="",$M22,ROUND(MEDIAN(60,$M22+$N22,100),3)) | Q22: =IF(COUNTIFS($A$6:$A$79,$A22,$F$6:$F$79,$F22)>1,"★동점","") | R22: =IF($L22="","",RANK.EQ($L22,$L$20:$L$35,1)) | S22: =IF($L22="","제5호 - 미실시",IF($R22=$H22,"보존","★불일치")) | T22: =$E22&"|"&$C22 | U22: =IF($G22<6,"",80+7*$K22/$I22) | V22: =IF($N22="",$M22,$M22+$N22)
A23: 평가군 3 | B23: 평가자 3 | C23: 1차 | D23: 5급 | E23: 직원18 | F23: 78.3 | G23: =COUNTIF($A$6:$A$79,$A23) | H23: =RANK.EQ($F23,$F$20:$F$35,1) | I23: =INDEX('s(n) 표'!$AQ$5:$AQ$43,MATCH($G23,'s(n) 표'!$A$5:$A$43,0)) | J23: =($H23-0.375)/($G23+0.25) | K23: =NORM.S.INV($J23) | L23: =IF($G23<6,"",ROUND(MEDIAN(60,80+7*$K23/$I23,100),3)) | M23: =IF($G23>=6,$L23,IFERROR(IF(INDEX($L$6:$L$79,MATCH($E23&"|2차",$T$6:$T$79,0))="",80,INDEX($L$6:$L$79,MATCH($E23&"|2차",$T$6:$T$79,0))),80)) | N23: 0 | O23: =IF($N23="",$M23,ROUND(MEDIAN(60,$M23+$N23,100),3)) | Q23: =IF(COUNTIFS($A$6:$A$79,$A23,$F$6:$F$79,$F23)>1,"★동점","") | R23: =IF($L23="","",RANK.EQ($L23,$L$20:$L$35,1)) | S23: =IF($L23="","제5호 - 미실시",IF($R23=$H23,"보존","★불일치")) | T23: =$E23&"|"&$C23 | U23: =IF($G23<6,"",80+7*$K23/$I23) | V23: =IF($N23="",$M23,$M23+$N23)
A24: 평가군 3 | B24: 평가자 3 | C24: 1차 | D24: 5급 | E24: 직원19 | F24: 78.4 | G24: =COUNTIF($A$6:$A$79,$A24) | H24: =RANK.EQ($F24,$F$20:$F$35,1) | I24: =INDEX('s(n) 표'!$AQ$5:$AQ$43,MATCH($G24,'s(n) 표'!$A$5:$A$43,0)) | J24: =($H24-0.375)/($G24+0.25) | K24: =NORM.S.INV($J24) | L24: =IF($G24<6,"",ROUND(MEDIAN(60,80+7*$K24/$I24,100),3)) | M24: =IF($G24>=6,$L24,IFERROR(IF(INDEX($L$6:$L$79,MATCH($E24&"|2차",$T$6:$T$79,0))="",80,INDEX($L$6:$L$79,MATCH($E24&"|2차",$T$6:$T$79,0))),80)) | N24: 0 | O24: =IF($N24="",$M24,ROUND(MEDIAN(60,$M24+$N24,100),3)) | Q24: =IF(COUNTIFS($A$6:$A$79,$A24,$F$6:$F$79,$F24)>1,"★동점","") | R24: =IF($L24="","",RANK.EQ($L24,$L$20:$L$35,1)) | S24: =IF($L24="","제5호 - 미실시",IF($R24=$H24,"보존","★불일치")) | T24: =$E24&"|"&$C24 | U24: =IF($G24<6,"",80+7*$K24/$I24) | V24: =IF($N24="",$M24,$M24+$N24)
A25: 평가군 3 | B25: 평가자 3 | C25: 1차 | D25: 5급 | E25: 직원20 | F25: 78.5 | G25: =COUNTIF($A$6:$A$79,$A25) | H25: =RANK.EQ($F25,$F$20:$F$35,1) | I25: =INDEX('s(n) 표'!$AQ$5:$AQ$43,MATCH($G25,'s(n) 표'!$A$5:$A$43,0)) | J25: =($H25-0.375)/($G25+0.25) | K25: =NORM.S.INV($J25) | L25: =IF($G25<6,"",ROUND(MEDIAN(60,80+7*$K25/$I25,100),3)) | M25: =IF($G25>=6,$L25,IFERROR(IF(INDEX($L$6:$L$79,MATCH($E25&"|2차",$T$6:$T$79,0))="",80,INDEX($L$6:$L$79,MATCH($E25&"|2차",$T$6:$T$79,0))),80)) | N25: 0 | O25: =IF($N25="",$M25,ROUND(MEDIAN(60,$M25+$N25,100),3)) | Q25: =IF(COUNTIFS($A$6:$A$79,$A25,$F$6:$F$79,$F25)>1,"★동점","") | R25: =IF($L25="","",RANK.EQ($L25,$L$20:$L$35,1)) | S25: =IF($L25="","제5호 - 미실시",IF($R25=$H25,"보존","★불일치")) | T25: =$E25&"|"&$C25 | U25: =IF($G25<6,"",80+7*$K25/$I25) | V25: =IF($N25="",$M25,$M25+$N25)
A26: 평가군 3 | B26: 평가자 3 | C26: 1차 | D26: 5급 | E26: 직원21 | F26: 78.6 | G26: =COUNTIF($A$6:$A$79,$A26) | H26: =RANK.EQ($F26,$F$20:$F$35,1) | I26: =INDEX('s(n) 표'!$AQ$5:$AQ$43,MATCH($G26,'s(n) 표'!$A$5:$A$43,0)) | J26: =($H26-0.375)/($G26+0.25) | K26: =NORM.S.INV($J26) | L26: =IF($G26<6,"",ROUND(MEDIAN(60,80+7*$K26/$I26,100),3)) | M26: =IF($G26>=6,$L26,IFERROR(IF(INDEX($L$6:$L$79,MATCH($E26&"|2차",$T$6:$T$79,0))="",80,INDEX($L$6:$L$79,MATCH($E26&"|2차",$T$6:$T$79,0))),80)) | N26: 0 | O26: =IF($N26="",$M26,ROUND(MEDIAN(60,$M26+$N26,100),3)) | Q26: =IF(COUNTIFS($A$6:$A$79,$A26,$F$6:$F$79,$F26)>1,"★동점","") | R26: =IF($L26="","",RANK.EQ($L26,$L$20:$L$35,1)) | S26: =IF($L26="","제5호 - 미실시",IF($R26=$H26,"보존","★불일치")) | T26: =$E26&"|"&$C26 | U26: =IF($G26<6,"",80+7*$K26/$I26) | V26: =IF($N26="",$M26,$M26+$N26)
A27: 평가군 3 | B27: 평가자 3 | C27: 1차 | D27: 5급 | E27: 직원22 | F27: 78.7 | G27: =COUNTIF($A$6:$A$79,$A27) | H27: =RANK.EQ($F27,$F$20:$F$35,1) | I27: =INDEX('s(n) 표'!$AQ$5:$AQ$43,MATCH($G27,'s(n) 표'!$A$5:$A$43,0)) | J27: =($H27-0.375)/($G27+0.25) | K27: =NORM.S.INV($J27) | L27: =IF($G27<6,"",ROUND(MEDIAN(60,80+7*$K27/$I27,100),3)) | M27: =IF($G27>=6,$L27,IFERROR(IF(INDEX($L$6:$L$79,MATCH($E27&"|2차",$T$6:$T$79,0))="",80,INDEX($L$6:$L$79,MATCH($E27&"|2차",$T$6:$T$79,0))),80)) | N27: 0 | O27: =IF($N27="",$M27,ROUND(MEDIAN(60,$M27+$N27,100),3)) | Q27: =IF(COUNTIFS($A$6:$A$79,$A27,$F$6:$F$79,$F27)>1,"★동점","") | R27: =IF($L27="","",RANK.EQ($L27,$L$20:$L$35,1)) | S27: =IF($L27="","제5호 - 미실시",IF($R27=$H27,"보존","★불일치")) | T27: =$E27&"|"&$C27 | U27: =IF($G27<6,"",80+7*$K27/$I27) | V27: =IF($N27="",$M27,$M27+$N27)
A28: 평가군 3 | B28: 평가자 3 | C28: 1차 | D28: 5급 | E28: 직원23 | F28: 78.8 | G28: =COUNTIF($A$6:$A$79,$A28) | H28: =RANK.EQ($F28,$F$20:$F$35,1) | I28: =INDEX('s(n) 표'!$AQ$5:$AQ$43,MATCH($G28,'s(n) 표'!$A$5:$A$43,0)) | J28: =($H28-0.375)/($G28+0.25) | K28: =NORM.S.INV($J28) | L28: =IF($G28<6,"",ROUND(MEDIAN(60,80+7*$K28/$I28,100),3)) | M28: =IF($G28>=6,$L28,IFERROR(IF(INDEX($L$6:$L$79,MATCH($E28&"|2차",$T$6:$T$79,0))="",80,INDEX($L$6:$L$79,MATCH($E28&"|2차",$T$6:$T$79,0))),80)) | N28: 0 | O28: =IF($N28="",$M28,ROUND(MEDIAN(60,$M28+$N28,100),3)) | Q28: =IF(COUNTIFS($A$6:$A$79,$A28,$F$6:$F$79,$F28)>1,"★동점","") | R28: =IF($L28="","",RANK.EQ($L28,$L$20:$L$35,1)) | S28: =IF($L28="","제5호 - 미실시",IF($R28=$H28,"보존","★불일치")) | T28: =$E28&"|"&$C28 | U28: =IF($G28<6,"",80+7*$K28/$I28) | V28: =IF($N28="",$M28,$M28+$N28)
A29: 평가군 3 | B29: 평가자 3 | C29: 1차 | D29: 5급 | E29: 직원24 | F29: 78.9 | G29: =COUNTIF($A$6:$A$79,$A29) | H29: =RANK.EQ($F29,$F$20:$F$35,1) | I29: =INDEX('s(n) 표'!$AQ$5:$AQ$43,MATCH($G29,'s(n) 표'!$A$5:$A$43,0)) | J29: =($H29-0.375)/($G29+0.25) | K29: =NORM.S.INV($J29) | L29: =IF($G29<6,"",ROUND(MEDIAN(60,80+7*$K29/$I29,100),3)) | M29: =IF($G29>=6,$L29,IFERROR(IF(INDEX($L$6:$L$79,MATCH($E29&"|2차",$T$6:$T$79,0))="",80,INDEX($L$6:$L$79,MATCH($E29&"|2차",$T$6:$T$79,0))),80)) | N29: 0 | O29: =IF($N29="",$M29,ROUND(MEDIAN(60,$M29+$N29,100),3)) | Q29: =IF(COUNTIFS($A$6:$A$79,$A29,$F$6:$F$79,$F29)>1,"★동점","") | R29: =IF($L29="","",RANK.EQ($L29,$L$20:$L$35,1)) | S29: =IF($L29="","제5호 - 미실시",IF($R29=$H29,"보존","★불일치")) | T29: =$E29&"|"&$C29 | U29: =IF($G29<6,"",80+7*$K29/$I29) | V29: =IF($N29="",$M29,$M29+$N29)
A30: 평가군 3 | B30: 평가자 3 | C30: 1차 | D30: 5급 | E30: 직원25 | F30: 79 | G30: =COUNTIF($A$6:$A$79,$A30) | H30: =RANK.EQ($F30,$F$20:$F$35,1) | I30: =INDEX('s(n) 표'!$AQ$5:$AQ$43,MATCH($G30,'s(n) 표'!$A$5:$A$43,0)) | J30: =($H30-0.375)/($G30+0.25) | K30: =NORM.S.INV($J30) | L30: =IF($G30<6,"",ROUND(MEDIAN(60,80+7*$K30/$I30,100),3)) | M30: =IF($G30>=6,$L30,IFERROR(IF(INDEX($L$6:$L$79,MATCH($E30&"|2차",$T$6:$T$79,0))="",80,INDEX($L$6:$L$79,MATCH($E30&"|2차",$T$6:$T$79,0))),80)) | N30: 0 | O30: =IF($N30="",$M30,ROUND(MEDIAN(60,$M30+$N30,100),3)) | Q30: =IF(COUNTIFS($A$6:$A$79,$A30,$F$6:$F$79,$F30)>1,"★동점","") | R30: =IF($L30="","",RANK.EQ($L30,$L$20:$L$35,1)) | S30: =IF($L30="","제5호 - 미실시",IF($R30=$H30,"보존","★불일치")) | T30: =$E30&"|"&$C30 | U30: =IF($G30<6,"",80+7*$K30/$I30) | V30: =IF($N30="",$M30,$M30+$N30)
A31: 평가군 3 | B31: 평가자 3 | C31: 1차 | D31: 5급 | E31: 직원26 | F31: 79.1 | G31: =COUNTIF($A$6:$A$79,$A31) | H31: =RANK.EQ($F31,$F$20:$F$35,1) | I31: =INDEX('s(n) 표'!$AQ$5:$AQ$43,MATCH($G31,'s(n) 표'!$A$5:$A$43,0)) | J31: =($H31-0.375)/($G31+0.25) | K31: =NORM.S.INV($J31) | L31: =IF($G31<6,"",ROUND(MEDIAN(60,80+7*$K31/$I31,100),3)) | M31: =IF($G31>=6,$L31,IFERROR(IF(INDEX($L$6:$L$79,MATCH($E31&"|2차",$T$6:$T$79,0))="",80,INDEX($L$6:$L$79,MATCH($E31&"|2차",$T$6:$T$79,0))),80)) | N31: 0 | O31: =IF($N31="",$M31,ROUND(MEDIAN(60,$M31+$N31,100),3)) | Q31: =IF(COUNTIFS($A$6:$A$79,$A31,$F$6:$F$79,$F31)>1,"★동점","") | R31: =IF($L31="","",RANK.EQ($L31,$L$20:$L$35,1)) | S31: =IF($L31="","제5호 - 미실시",IF($R31=$H31,"보존","★불일치")) | T31: =$E31&"|"&$C31 | U31: =IF($G31<6,"",80+7*$K31/$I31) | V31: =IF($N31="",$M31,$M31+$N31)
... A35: 평가군 3 | B35: 평가자 3 | C35: 1차 | D35: 5급 | E35: 직원30 | F35: 79.5 | G35: =COUNTIF($A$6:$A$79,$A35) | H35: =RANK.EQ($F35,$F$20:$F$35,1) | I35: =INDEX('s(n) 표'!$AQ$5:$AQ$43,MATCH($G35,'s(n) 표'!$A$5:$A$43,0)) | J35: =($H35-0.375)/($G35+0.25) | K35: =NORM.S.INV($J35) | L35: =IF($G35<6,"",ROUND(MEDIAN(60,80+7*$K35/$I35,100),3)) | M35: =IF($G35>=6,$L35,IFERROR(IF(INDEX($L$6:$L$79,MATCH($E35&"|2차",$T$6:$T$79,0))="",80,INDEX($L$6:$L$79,MATCH($E35&"|2차",$T$6:$T$79,0))),80)) | N35: 0 | O35: =IF($N35="",$M35,ROUND(MEDIAN(60,$M35+$N35,100),3)) | Q35: =IF(COUNTIFS($A$6:$A$79,$A35,$F$6:$F$79,$F35)>1,"★동점","") | R35: =IF($L35="","",RANK.EQ($L35,$L$20:$L$35,1)) | S35: =IF($L35="","제5호 - 미실시",IF($R35=$H35,"보존","★불일치")) | T35: =$E35&"|"&$C35 | U35: =IF($G35<6,"",80+7*$K35/$I35) | V35: =IF($N35="",$M35,$M35+$N35)
A36: 평가군 4 | B36: 평가자 4 | C36: 2차 | D36: 5급 | E36: 직원01 | F36: 96 | G36: =COUNTIF($A$6:$A$79,$A36) | H36: =RANK.EQ($F36,$F$36:$F$65,1) | I36: =INDEX('s(n) 표'!$AQ$5:$AQ$43,MATCH($G36,'s(n) 표'!$A$5:$A$43,0)) | J36: =($H36-0.375)/($G36+0.25) | K36: =NORM.S.INV($J36) | L36: =IF($G36<6,"",ROUND(MEDIAN(60,80+7*$K36/$I36,100),3)) | M36: =IF($G36>=6,$L36,IFERROR(IF(INDEX($L$6:$L$79,MATCH($E36&"|2차",$T$6:$T$79,0))="",80,INDEX($L$6:$L$79,MATCH($E36&"|2차",$T$6:$T$79,0))),80)) | N36: 0 | O36: =IF($N36="",$M36,ROUND(MEDIAN(60,$M36+$N36,100),3)) | P36: 해당 없음 (제7호 조정은 1차 평가자만) | Q36: =IF(COUNTIFS($A$6:$A$79,$A36,$F$6:$F$79,$F36)>1,"★동점","") | R36: =IF($L36="","",RANK.EQ($L36,$L$36:$L$65,1)) | S36: =IF($L36="","제5호 - 미실시",IF($R36=$H36,"보존","★불일치")) | T36: =$E36&"|"&$C36 | U36: =IF($G36<6,"",80+7*$K36/$I36) | V36: =IF($N36="",$M36,$M36+$N36)
A37: 평가군 4 | B37: 평가자 4 | C37: 2차 | D37: 5급 | E37: 직원02 | F37: 91 | G37: =COUNTIF($A$6:$A$79,$A37) | H37: =RANK.EQ($F37,$F$36:$F$65,1) | I37: =INDEX('s(n) 표'!$AQ$5:$AQ$43,MATCH($G37,'s(n) 표'!$A$5:$A$43,0)) | J37: =($H37-0.375)/($G37+0.25) | K37: =NORM.S.INV($J37) | L37: =IF($G37<6,"",ROUND(MEDIAN(60,80+7*$K37/$I37,100),3)) | M37: =IF($G37>=6,$L37,IFERROR(IF(INDEX($L$6:$L$79,MATCH($E37&"|2차",$T$6:$T$79,0))="",80,INDEX($L$6:$L$79,MATCH($E37&"|2차",$T$6:$T$79,0))),80)) | N37: 0 | O37: =IF($N37="",$M37,ROUND(MEDIAN(60,$M37+$N37,100),3)) | P37: 해당 없음 (제7호 조정은 1차 평가자만) | Q37: =IF(COUNTIFS($A$6:$A$79,$A37,$F$6:$F$79,$F37)>1,"★동점","") | R37: =IF($L37="","",RANK.EQ($L37,$L$36:$L$65,1)) | S37: =IF($L37="","제5호 - 미실시",IF($R37=$H37,"보존","★불일치")) | T37: =$E37&"|"&$C37 | U37: =IF($G37<6,"",80+7*$K37/$I37) | V37: =IF($N37="",$M37,$M37+$N37)
A38: 평가군 4 | B38: 평가자 4 | C38: 2차 | D38: 5급 | E38: 직원03 | F38: 94 | G38: =COUNTIF($A$6:$A$79,$A38) | H38: =RANK.EQ($F38,$F$36:$F$65,1) | I38: =INDEX('s(n) 표'!$AQ$5:$AQ$43,MATCH($G38,'s(n) 표'!$A$5:$A$43,0)) | J38: =($H38-0.375)/($G38+0.25) | K38: =NORM.S.INV($J38) | L38: =IF($G38<6,"",ROUND(MEDIAN(60,80+7*$K38/$I38,100),3)) | M38: =IF($G38>=6,$L38,IFERROR(IF(INDEX($L$6:$L$79,MATCH($E38&"|2차",$T$6:$T$79,0))="",80,INDEX($L$6:$L$79,MATCH($E38&"|2차",$T$6:$T$79,0))),80)) | N38: 0 | O38: =IF($N38="",$M38,ROUND(MEDIAN(60,$M38+$N38,100),3)) | P38: 해당 없음 (제7호 조정은 1차 평가자만) | Q38: =IF(COUNTIFS($A$6:$A$79,$A38,$F$6:$F$79,$F38)>1,"★동점","") | R38: =IF($L38="","",RANK.EQ($L38,$L$36:$L$65,1)) | S38: =IF($L38="","제5호 - 미실시",IF($R38=$H38,"보존","★불일치")) | T38: =$E38&"|"&$C38 | U38: =IF($G38<6,"",80+7*$K38/$I38) | V38: =IF($N38="",$M38,$M38+$N38)
A39: 평가군 4 | B39: 평가자 4 | C39: 2차 | D39: 5급 | E39: 직원04 | F39: 87 | G39: =COUNTIF($A$6:$A$79,$A39) | H39: =RANK.EQ($F39,$F$36:$F$65,1) | I39: =INDEX('s(n) 표'!$AQ$5:$AQ$43,MATCH($G39,'s(n) 표'!$A$5:$A$43,0)) | J39: =($H39-0.375)/($G39+0.25) | K39: =NORM.S.INV($J39) | L39: =IF($G39<6,"",ROUND(MEDIAN(60,80+7*$K39/$I39,100),3)) | M39: =IF($G39>=6,$L39,IFERROR(IF(INDEX($L$6:$L$79,MATCH($E39&"|2차",$T$6:$T$79,0))="",80,INDEX($L$6:$L$79,MATCH($E39&"|2차",$T$6:$T$79,0))),80)) | N39: 0 | O39: =IF($N39="",$M39,ROUND(MEDIAN(60,$M39+$N39,100),3)) | P39: 해당 없음 (제7호 조정은 1차 평가자만) | Q39: =IF(COUNTIFS($A$6:$A$79,$A39,$F$6:$F$79,$F39)>1,"★동점","") | R39: =IF($L39="","",RANK.EQ($L39,$L$36:$L$65,1)) | S39: =IF($L39="","제5호 - 미실시",IF($R39=$H39,"보존","★불일치")) | T39: =$E39&"|"&$C39 | U39: =IF($G39<6,"",80+7*$K39/$I39) | V39: =IF($N39="",$M39,$M39+$N39)
A40: 평가군 4 | B40: 평가자 4 | C40: 2차 | D40: 5급 | E40: 직원05 | F40: 82 | G40: =COUNTIF($A$6:$A$79,$A40) | H40: =RANK.EQ($F40,$F$36:$F$65,1) | I40: =INDEX('s(n) 표'!$AQ$5:$AQ$43,MATCH($G40,'s(n) 표'!$A$5:$A$43,0)) | J40: =($H40-0.375)/($G40+0.25) | K40: =NORM.S.INV($J40) | L40: =IF($G40<6,"",ROUND(MEDIAN(60,80+7*$K40/$I40,100),3)) | M40: =IF($G40>=6,$L40,IFERROR(IF(INDEX($L$6:$L$79,MATCH($E40&"|2차",$T$6:$T$79,0))="",80,INDEX($L$6:$L$79,MATCH($E40&"|2차",$T$6:$T$79,0))),80)) | N40: 0 | O40: =IF($N40="",$M40,ROUND(MEDIAN(60,$M40+$N40,100),3)) | P40: 해당 없음 (제7호 조정은 1차 평가자만) | Q40: =IF(COUNTIFS($A$6:$A$79,$A40,$F$6:$F$79,$F40)>1,"★동점","") | R40: =IF($L40="","",RANK.EQ($L40,$L$36:$L$65,1)) | S40: =IF($L40="","제5호 - 미실시",IF($R40=$H40,"보존","★불일치")) | T40: =$E40&"|"&$C40 | U40: =IF($G40<6,"",80+7*$K40/$I40) | V40: =IF($N40="",$M40,$M40+$N40)
A41: 평가군 4 | B41: 평가자 4 | C41: 2차 | D41: 5급 | E41: 직원06 | F41: 79 | G41: =COUNTIF($A$6:$A$79,$A41) | H41: =RANK.EQ($F41,$F$36:$F$65,1) | I41: =INDEX('s(n) 표'!$AQ$5:$AQ$43,MATCH($G41,'s(n) 표'!$A$5:$A$43,0)) | J41: =($H41-0.375)/($G41+0.25) | K41: =NORM.S.INV($J41) | L41: =IF($G41<6,"",ROUND(MEDIAN(60,80+7*$K41/$I41,100),3)) | M41: =IF($G41>=6,$L41,IFERROR(IF(INDEX($L$6:$L$79,MATCH($E41&"|2차",$T$6:$T$79,0))="",80,INDEX($L$6:$L$79,MATCH($E41&"|2차",$T$6:$T$79,0))),80)) | N41: 0 | O41: =IF($N41="",$M41,ROUND(MEDIAN(60,$M41+$N41,100),3)) | P41: 해당 없음 (제7호 조정은 1차 평가자만) | Q41: =IF(COUNTIFS($A$6:$A$79,$A41,$F$6:$F$79,$F41)>1,"★동점","") | R41: =IF($L41="","",RANK.EQ($L41,$L$36:$L$65,1)) | S41: =IF($L41="","제5호 - 미실시",IF($R41=$H41,"보존","★불일치")) | T41: =$E41&"|"&$C41 | U41: =IF($G41<6,"",80+7*$K41/$I41) | V41: =IF($N41="",$M41,$M41+$N41)
A42: 평가군 4 | B42: 평가자 4 | C42: 2차 | D42: 5급 | E42: 직원07 | F42: 74 | G42: =COUNTIF($A$6:$A$79,$A42) | H42: =RANK.EQ($F42,$F$36:$F$65,1) | I42: =INDEX('s(n) 표'!$AQ$5:$AQ$43,MATCH($G42,'s(n) 표'!$A$5:$A$43,0)) | J42: =($H42-0.375)/($G42+0.25) | K42: =NORM.S.INV($J42) | L42: =IF($G42<6,"",ROUND(MEDIAN(60,80+7*$K42/$I42,100),3)) | M42: =IF($G42>=6,$L42,IFERROR(IF(INDEX($L$6:$L$79,MATCH($E42&"|2차",$T$6:$T$79,0))="",80,INDEX($L$6:$L$79,MATCH($E42&"|2차",$T$6:$T$79,0))),80)) | N42: 0 | O42: =IF($N42="",$M42,ROUND(MEDIAN(60,$M42+$N42,100),3)) | P42: 해당 없음 (제7호 조정은 1차 평가자만) | Q42: =IF(COUNTIFS($A$6:$A$79,$A42,$F$6:$F$79,$F42)>1,"★동점","") | R42: =IF($L42="","",RANK.EQ($L42,$L$36:$L$65,1)) | S42: =IF($L42="","제5호 - 미실시",IF($R42=$H42,"보존","★불일치")) | T42: =$E42&"|"&$C42 | U42: =IF($G42<6,"",80+7*$K42/$I42) | V42: =IF($N42="",$M42,$M42+$N42)
A43: 평가군 4 | B43: 평가자 4 | C43: 2차 | D43: 5급 | E43: 직원08 | F43: 77 | G43: =COUNTIF($A$6:$A$79,$A43) | H43: =RANK.EQ($F43,$F$36:$F$65,1) | I43: =INDEX('s(n) 표'!$AQ$5:$AQ$43,MATCH($G43,'s(n) 표'!$A$5:$A$43,0)) | J43: =($H43-0.375)/($G43+0.25) | K43: =NORM.S.INV($J43) | L43: =IF($G43<6,"",ROUND(MEDIAN(60,80+7*$K43/$I43,100),3)) | M43: =IF($G43>=6,$L43,IFERROR(IF(INDEX($L$6:$L$79,MATCH($E43&"|2차",$T$6:$T$79,0))="",80,INDEX($L$6:$L$79,MATCH($E43&"|2차",$T$6:$T$79,0))),80)) | N43: 0 | O43: =IF($N43="",$M43,ROUND(MEDIAN(60,$M43+$N43,100),3)) | P43: 해당 없음 (제7호 조정은 1차 평가자만) | Q43: =IF(COUNTIFS($A$6:$A$79,$A43,$F$6:$F$79,$F43)>1,"★동점","") | R43: =IF($L43="","",RANK.EQ($L43,$L$36:$L$65,1)) | S43: =IF($L43="","제5호 - 미실시",IF($R43=$H43,"보존","★불일치")) | T43: =$E43&"|"&$C43 | U43: =IF($G43<6,"",80+7*$K43/$I43) | V43: =IF($N43="",$M43,$M43+$N43)
...

Sheet 종합점수·등급
A1: ③ 종합점수·등급 — 규칙 제9조② · 제26조① · [별표 2] · [별표 7]
A2: 고지 — 이 파일의 모든 인명·점수는 산식 검증을 위한 모의 예시 데이터이며, 창업진흥원의 실제 근무평정 결과가 아니다.
A3: 개정 14 채택 여부 (Y/N) → | B3: Y | C3: ★ 배점 스위치 — Y: 업적·역량 75% / 다면 20% / 공통 5% N(현행): 85% / 10% / 5%
A4: 업적·역량 배점 | B4: =IF($B$3="Y",0.75,0.85)
A5: 다면(상향) 배점 | B5: =IF($B$3="Y",0.2,0.1)
A6: 공통평가 배점 | B6: 0.05 | C6: 부서장(4급 이상)은 다면 대신 상향평가이며 1차:2차 = 50:50, 배점은 현행(0.85/0.10/0.05)을 유지한다.
C7: [별표 9] 제5호 적용 행(1차 평가군 6명 미만)은 1차 비율 0 · 2차 비율 100%이며, 업적·역량 = 2차 보정점수 × 100% + 1차 평가자의 제7호 조정량(E열 − F열)이다.
A8: 직원 | B8: 직급 | C8: 부서장 여부 | D8: 1차 평가군 인원 n₁ | E8: 1차 적용점수 (조정 후) 제5호 시 = 2차+조정 | F8: 2차 보정점수 | G8: 제5호 | H8: 1차 비율 | I8: 2차 비율 | J8: 업적·역량 점수 | K8: 다면/상향 원점수 | L8: 유효 응답수 | M8: 다면 평가군 인원 | N8: 다면 순위 | O8: 다면 s(n) | P8: 다면 보정점수 | Q8: 공통평가 | R8: 업적·역량 배점 | S8: 다면 배점 | T8: 종합점수 | U8: 직급 인원 | V8: 직급내 순위 | W8: S 정원 | X8: A 정원 | Y8: B 정원 | Z8: C 정원 | AA8: 등급 | AB8: 등급 인원 | AC8: 등급내 순위 | AD8: 평정점 (별표 7)
A9: 직원01 | B9: 5급 | C9: N | D9: =INDEX('평가군 계산'!$G$6:$G$79,MATCH($A9&"|1차",'평가군 계산'!$T$6:$T$79,0)) | E9: =INDEX('평가군 계산'!$O$6:$O$79,MATCH($A9&"|1차",'평가군 계산'!$T$6:$T$79,0)) | F9: =IFERROR(IF(INDEX('평가군 계산'!$L$6:$L$79,MATCH($A9&"|2차",'평가군 계산'!$T$6:$T$79,0))="",80,INDEX('평가군 계산'!$L$6:$L$79,MATCH($A9&"|2차",'평가군 계산'!$T$6:$T$79,0))),80) | G9: =IF($D9<6,"제5호 — 2차 100% + 1차 조정","-") | H9: =IF($D9<6,0,IF($C9="Y",0.5,0.6)) | I9: =IF($D9<6,1,IF($C9="Y",0.5,0.4)) | J9: =ROUND(IF($D9<6,$I9*$F9+($E9-$F9),$H9*$E9+$I9*$F9),3) | K9: 79.1 | L9: 7 | M9: =COUNTIFS($L$9:$L$45,">=3") | N9: =IF($L9<3,"",COUNTIFS($L$9:$L$45,">=3",$K$9:$K$45,"<"&$K9)+1) | O9: =IF($L9<3,"",INDEX('s(n) 표'!$AQ$5:$AQ$43,MATCH($M9,'s(n) 표'!$A$5:$A$43,0))) | P9: =IF($L9<3,80,ROUND(MEDIAN(60,80+7*NORM.S.INV(($N9-0.375)/($M9+0.25))/$O9,100),3)) | Q9: 97 | R9: =IF($C9="Y",0.85,$B$4)+IF($L9<3,IF($C9="Y",0.1,$B$5),0) | S9: =IF($L9<3,0,IF($C9="Y",0.1,$B$5)) | T9: =ROUND($R9*$J9+$S9*$P9+$B$6*$Q9,3) | U9: =COUNTIF($B$9:$B$45,$B9) | V9: =COUNTIFS($B$9:$B$45,$B9,$T$9:$T$45,">"&$T9)+1 | W9: =INDEX($T$50:$T$51,MATCH($B9,$A$50:$A$51,0)) | X9: =INDEX($U$50:$U$51,MATCH($B9,$A$50:$A$51,0)) | Y9: =INDEX($V$50:$V$51,MATCH($B9,$A$50:$A$51,0)) | Z9: =INDEX($W$50:$W$51,MATCH($B9,$A$50:$A$51,0)) | AA9: =IF($V9<=$W9,"S",IF($V9<=$W9+$X9,"A",IF($V9<=$W9+$X9+$Y9,"B","C"))) | AB9: =IF($AA9="S",$W9,IF($AA9="A",$X9,IF($AA9="B",$Y9,$Z9))) | AC9: =$V9-IF($AA9="S",0,IF($AA9="A",$W9,IF($AA9="B",$W9+$X9,$W9+$X9+$Y9))) | AD9: =ROUND(IF($AA9="S",100,IF($AA9="A",90,IF($AA9="B",80,70)))-(10/$AB9)*($AC9-1),3)
A10: 직원02 | B10: 5급 | C10: N | D10: =INDEX('평가군 계산'!$G$6:$G$79,MATCH($A10&"|1차",'평가군 계산'!$T$6:$T$79,0)) | E10: =INDEX('평가군 계산'!$O$6:$O$79,MATCH($A10&"|1차",'평가군 계산'!$T$6:$T$79,0)) | F10: =IFERROR(IF(INDEX('평가군 계산'!$L$6:$L$79,MATCH($A10&"|2차",'평가군 계산'!$T$6:$T$79,0))="",80,INDEX('평가군 계산'!$L$6:$L$79,MATCH($A10&"|2차",'평가군 계산'!$T$6:$T$79,0))),80) | G10: =IF($D10<6,"제5호 — 2차 100% + 1차 조정","-") | H10: =IF($D10<6,0,IF($C10="Y",0.5,0.6)) | I10: =IF($D10<6,1,IF($C10="Y",0.5,0.4)) | J10: =ROUND(IF($D10<6,$I10*$F10+($E10-$F10),$H10*$E10+$I10*$F10),3) | K10: 88.2 | L10: 8 | M10: =COUNTIFS($L$9:$L$45,">=3") | N10: =IF($L10<3,"",COUNTIFS($L$9:$L$45,">=3",$K$9:$K$45,"<"&$K10)+1) | O10: =IF($L10<3,"",INDEX('s(n) 표'!$AQ$5:$AQ$43,MATCH($M10,'s(n) 표'!$A$5:$A$43,0))) | P10: =IF($L10<3,80,ROUND(MEDIAN(60,80+7*NORM.S.INV(($N10-0.375)/($M10+0.25))/$O10,100),3)) | Q10: 93 | R10: =IF($C10="Y",0.85,$B$4)+IF($L10<3,IF($C10="Y",0.1,$B$5),0) | S10: =IF($L10<3,0,IF($C10="Y",0.1,$B$5)) | T10: =ROUND($R10*$J10+$S10*$P10+$B$6*$Q10,3) | U10: =COUNTIF($B$9:$B$45,$B10) | V10: =COUNTIFS($B$9:$B$45,$B10,$T$9:$T$45,">"&$T10)+1 | W10: =INDEX($T$50:$T$51,MATCH($B10,$A$50:$A$51,0)) | X10: =INDEX($U$50:$U$51,MATCH($B10,$A$50:$A$51,0)) | Y10: =INDEX($V$50:$V$51,MATCH($B10,$A$50:$A$51,0)) | Z10: =INDEX($W$50:$W$51,MATCH($B10,$A$50:$A$51,0)) | AA10: =IF($V10<=$W10,"S",IF($V10<=$W10+$X10,"A",IF($V10<=$W10+$X10+$Y10,"B","C"))) | AB10: =IF($AA10="S",$W10,IF($AA10="A",$X10,IF($AA10="B",$Y10,$Z10))) | AC10: =$V10-IF($AA10="S",0,IF($AA10="A",$W10,IF($AA10="B",$W10+$X10,$W10+$X10+$Y10))) | AD10: =ROUND(IF($AA10="S",100,IF($AA10="A",90,IF($AA10="B",80,70)))-(10/$AB10)*($AC10-1),3)
A11: 직원03 | B11: 5급 | C11: N | D11: =INDEX('평가군 계산'!$G$6:$G$79,MATCH($A11&"|1차",'평가군 계산'!$T$6:$T$79,0)) | E11: =INDEX('평가군 계산'!$O$6:$O$79,MATCH($A11&"|1차",'평가군 계산'!$T$6:$T$79,0)) | F11: =IFERROR(IF(INDEX('평가군 계산'!$L$6:$L$79,MATCH($A11&"|2차",'평가군 계산'!$T$6:$T$79,0))="",80,INDEX('평가군 계산'!$L$6:$L$79,MATCH($A11&"|2차",'평가군 계산'!$T$6:$T$79,0))),80) | G11: =IF($D11<6,"제5호 — 2차 100% + 1차 조정","-") | H11: =IF($D11<6,0,IF($C11="Y",0.5,0.6)) | I11: =IF($D11<6,1,IF($C11="Y",0.5,0.4)) | J11: =ROUND(IF($D11<6,$I11*$F11+($E11-$F11),$H11*$E11+$I11*$F11),3) | K11: 71.4 | L11: 9 | M11: =COUNTIFS($L$9:$L$45,">=3") | N11: =IF($L11<3,"",COUNTIFS($L$9:$L$45,">=3",$K$9:$K$45,"<"&$K11)+1) | O11: =IF($L11<3,"",INDEX('s(n) 표'!$AQ$5:$AQ$43,MATCH($M11,'s(n) 표'!$A$5:$A$43,0))) | P11: =IF($L11<3,80,ROUND(MEDIAN(60,80+7*NORM.S.INV(($N11-0.375)/($M11+0.25))/$O11,100),3)) | Q11: 100 | R11: =IF($C11="Y",0.85,$B$4)+IF($L11<3,IF($C11="Y",0.1,$B$5),0) | S11: =IF($L11<3,0,IF($C11="Y",0.1,$B$5)) | T11: =ROUND($R11*$J11+$S11*$P11+$B$6*$Q11,3) | U11: =COUNTIF($B$9:$B$45,$B11) | V11: =COUNTIFS($B$9:$B$45,$B11,$T$9:$T$45,">"&$T11)+1 | W11: =INDEX($T$50:$T$51,MATCH($B11,$A$50:$A$51,0)) | X11: =INDEX($U$50:$U$51,MATCH($B11,$A$50:$A$51,0)) | Y11: =INDEX($V$50:$V$51,MATCH($B11,$A$50:$A$51,0)) | Z11: =INDEX($W$50:$W$51,MATCH($B11,$A$50:$A$51,0)) | AA11: =IF($V11<=$W11,"S",IF($V11<=$W11+$X11,"A",IF($V11<=$W11+$X11+$Y11,"B","C"))) | AB11: =IF($AA11="S",$W11,IF($AA11="A",$X11,IF($AA11="B",$Y11,$Z11))) | AC11: =$V11-IF($AA11="S",0,IF($AA11="A",$W11,IF($AA11="B",$W11+$X11,$W11+$X11+$Y11))) | AD11: =ROUND(IF($AA11="S",100,IF($AA11="A",90,IF($AA11="B",80,70)))-(10/$AB11)*($AC11-1),3)
A12: 직원04 | B12: 5급 | C12: N | D12: =INDEX('평가군 계산'!$G$6:$G$79,MATCH($A12&"|1차",'평가군 계산'!$T$6:$T$79,0)) | E12: =INDEX('평가군 계산'!$O$6:$O$79,MATCH($A12&"|1차",'평가군 계산'!$T$6:$T$79,0)) | F12: =IFERROR(IF(INDEX('평가군 계산'!$L$6:$L$79,MATCH($A12&"|2차",'평가군 계산'!$T$6:$T$79,0))="",80,INDEX('평가군 계산'!$L$6:$L$79,MATCH($A12&"|2차",'평가군 계산'!$T$6:$T$79,0))),80) | G12: =IF($D12<6,"제5호 — 2차 100% + 1차 조정","-") | H12: =IF($D12<6,0,IF($C12="Y",0.5,0.6)) | I12: =IF($D12<6,1,IF($C12="Y",0.5,0.4)) | J12: =ROUND(IF($D12<6,$I12*$F12+($E12-$F12),$H12*$E12+$I12*$F12),3) | K12: 80.5 | L12: 10 | M12: =COUNTIFS($L$9:$L$45,">=3") | N12: =IF($L12<3,"",COUNTIFS($L$9:$L$45,">=3",$K$9:$K$45,"<"&$K12)+1) | O12: =IF($L12<3,"",INDEX('s(n) 표'!$AQ$5:$AQ$43,MATCH($M12,'s(n) 표'!$A$5:$A$43,0))) | P12: =IF($L12<3,80,ROUND(MEDIAN(60,80+7*NORM.S.INV(($N12-0.375)/($M12+0.25))/$O12,100),3)) | Q12: 96 | R12: =IF($C12="Y",0.85,$B$4)+IF($L12<3,IF($C12="Y",0.1,$B$5),0) | S12: =IF($L12<3,0,IF($C12="Y",0.1,$B$5)) | T12: =ROUND($R12*$J12+$S12*$P12+$B$6*$Q12,3) | U12: =COUNTIF($B$9:$B$45,$B12) | V12: =COUNTIFS($B$9:$B$45,$B12,$T$9:$T$45,">"&$T12)+1 | W12: =INDEX($T$50:$T$51,MATCH($B12,$A$50:$A$51,0)) | X12: =INDEX($U$50:$U$51,MATCH($B12,$A$50:$A$51,0)) | Y12: =INDEX($V$50:$V$51,MATCH($B12,$A$50:$A$51,0)) | Z12: =INDEX($W$50:$W$51,MATCH($B12,$A$50:$A$51,0)) | AA12: =IF($V12<=$W12,"S",IF($V12<=$W12+$X12,"A",IF($V12<=$W12+$X12+$Y12,"B","C"))) | AB12: =IF($AA12="S",$W12,IF($AA12="A",$X12,IF($AA12="B",$Y12,$Z12))) | AC12: =$V12-IF($AA12="S",0,IF($AA12="A",$W12,IF($AA12="B",$W12+$X12,$W12+$X12+$Y12))) | AD12: =ROUND(IF($AA12="S",100,IF($AA12="A",90,IF($AA12="B",80,70)))-(10/$AB12)*($AC12-1),3)
A13: 직원05 | B13: 5급 | C13: N | D13: =INDEX('평가군 계산'!$G$6:$G$79,MATCH($A13&"|1차",'평가군 계산'!$T$6:$T$79,0)) | E13: =INDEX('평가군 계산'!$O$6:$O$79,MATCH($A13&"|1차",'평가군 계산'!$T$6:$T$79,0)) | F13: =IFERROR(IF(INDEX('평가군 계산'!$L$6:$L$79,MATCH($A13&"|2차",'평가군 계산'!$T$6:$T$79,0))="",80,INDEX('평가군 계산'!$L$6:$L$79,MATCH($A13&"|2차",'평가군 계산'!$T$6:$T$79,0))),80) | G13: =IF($D13<6,"제5호 — 2차 100% + 1차 조정","-") | H13: =IF($D13<6,0,IF($C13="Y",0.5,0.6)) | I13: =IF($D13<6,1,IF($C13="Y",0.5,0.4)) | J13: =ROUND(IF($D13<6,$I13*$F13+($E13-$F13),$H13*$E13+$I13*$F13),3) | K13: 89.6 | L13: 6 | M13: =COUNTIFS($L$9:$L$45,">=3") | N13: =IF($L13<3,"",COUNTIFS($L$9:$L$45,">=3",$K$9:$K$45,"<"&$K13)+1) | O13: =IF($L13<3,"",INDEX('s(n) 표'!$AQ$5:$AQ$43,MATCH($M13,'s(n) 표'!$A$5:$A$43,0))) | P13: =IF($L13<3,80,ROUND(MEDIAN(60,80+7*NORM.S.INV(($N13-0.375)/($M13+0.25))/$O13,100),3)) | Q13: 92 | R13: =IF($C13="Y",0.85,$B$4)+IF($L13<3,IF($C13="Y",0.1,$B$5),0) | S13: =IF($L13<3,0,IF($C13="Y",0.1,$B$5)) | T13: =ROUND($R13*$J13+$S13*$P13+$B$6*$Q13,3) | U13: =COUNTIF($B$9:$B$45,$B13) | V13: =COUNTIFS($B$9:$B$45,$B13,$T$9:$T$45,">"&$T13)+1 | W13: =INDEX($T$50:$T$51,MATCH($B13,$A$50:$A$51,0)) | X13: =INDEX($U$50:$U$51,MATCH($B13,$A$50:$A$51,0)) | Y13: =INDEX($V$50:$V$51,MATCH($B13,$A$50:$A$51,0)) | Z13: =INDEX($W$50:$W$51,MATCH($B13,$A$50:$A$51,0)) | AA13: =IF($V13<=$W13,"S",IF($V13<=$W13+$X13,"A",IF($V13<=$W13+$X13+$Y13,"B","C"))) | AB13: =IF($AA13="S",$W13,IF($AA13="A",$X13,IF($AA13="B",$Y13,$Z13))) | AC13: =$V13-IF($AA13="S",0,IF($AA13="A",$W13,IF($AA13="B",$W13+$X13,$W13+$X13+$Y13))) | AD13: =ROUND(IF($AA13="S",100,IF($AA13="A",90,IF($AA13="B",80,70)))-(10/$AB13)*($AC13-1),3)
